Workbook

Sheet TMMi - Visão Institucional
B2: Visão do TMMi a nível organizacional
B3: Nível TMMi | C3: Área de Processo | D3: Status Institucional | E3: Observação
B4: Nível 2 | C4: Política e Estratégia de Testes | D4: Desenvolvendo | E4: Política aplicada na prática, porém ainda em formalização (versão “Lite” em construção).
C5: Planejamento de Testes | D5: Adotado | E5: Planejamento por risco (P1/P2/P3) definido e replicável nas squads.
C6: Monitoramento e Controle dos Testes | D6: Adotado | E6: Métricas, dashboards e acompanhamento recorrente já existentes.
C7: Desenho e Execução de Testes | D7: Adotado | E7: Padrões de execução e evidência definidos (manual + automação).
C8: Gerenciamento de Defeitos | D8: Adotado | E8: Fluxo institucionalizado e utilizado pelas squads.
C9: Ambiente de Testes | D9: Adotado | E9: Ambiente de STG existente e utilizado (governança em evolução).
B10: Nível 3 | C10: Organização de Testes | D10: Em Adoção | E10: Chapter estruturado; maturidade varia entre squads.
C11: Programa de Treinamento em Testes | D11: Em Adoção | E11: Conteúdos e práticas existem, ainda sem formalização completa.
C12: Integração dos Testes ao SDLC | D12: Em Adoção | E12: Quality Review e upstream presentes em parte das squads.
C13: Testes Não Funcionais | D13: Desenvolvendo | E13: Iniciativas pontuais; estratégia e cadência em construção.
C14: Revisões Técnicas (Quality Review) | D14: Adotado | E14: Prática definida, utilizada e replicável nas squads mais maduras com Quality Strategy
B15: Nível 4 | C15: Medição dos Testes | D15: Em Adoção | E15: Indicadores comparáveis iniciados; consolidação virá como consequência do N2/N3.
C16: Avaliação da Qualidade do Produto | D16: Em Adoção | E16: Análises por produto/jornada começando a partir de dados reais.
C17: Revisões Avançadas | D17: Não Iniciado | E17: Análises por produto/jornada começando a partir de dados reais.

Sheet TMMi - Visão Squads
B2: Visão 2026 - Atualizada
B3: ID MELHORIA | C3: Trimestre | D3: Fase | E3: Nível e Área de Processo | F3: Envolvidos | G3: SQUAD CARTÕES
G4: ATIVOS | H4: DEMONSTRAÇÕES | I4: OPERAÇÕES | J4: PLATAFORMA | K4: VERUS
B5: T1-N2-N3-01 | C5: TRI 1 | D5: Engenharia de Qualidade | E5: N2 – Ambiente de Testes N3 – Organização de Testes | F5: Cloud / Engenharia / QA / Tech Leads | G5: ='Score TMMi'!H8 -> PLANEJADO | H5: ='Score TMMi'!H21 -> PLANEJADO | I5: ='Score TMMi'!H34 -> PLANEJADO | J5: ='Score TMMi'!H47 -> PLANEJADO | K5: ='Score TMMi'!H60 -> PLANEJADO
B6: T1-N2-02 | C6: TRI 1 | D6: Engenharia de Qualidade | E6: N2 – Política de Testes | F6: QA / Gestão | G6: ='Score TMMi'!H4 -> DESENVOLVENDO | H6: ='Score TMMi'!H4 -> DESENVOLVENDO | I6: ='Score TMMi'!H4 -> DESENVOLVENDO | J6: ='Score TMMi'!H4 -> DESENVOLVENDO | K6: ='Score TMMi'!H4 -> DESENVOLVENDO
B7: T1-N2-N4-03 | C7: TRI 1 | D7: Engenharia de Qualidade | E7: N4 – Medição dos Testes N2 – Monitoramento e Controle | F7: QA / Gestão | G7: ='Score TMMi'!H5 -> DESENVOLVENDO | H7: ='Score TMMi'!H5 -> DESENVOLVENDO | I7: ='Score TMMi'!H5 -> DESENVOLVENDO | J7: ='Score TMMi'!H5 -> DESENVOLVENDO | K7: ='Score TMMi'!H5 -> DESENVOLVENDO
B8: T1-N2-04 | C8: TRI 1 | D8: Engenharia de Qualidade | E8: N2 – Planejamento de Testes - Levantamento | F8: QA / Produto / Squad | G8: ='Score TMMi'!H10 -> PLANEJADO | H8: ='Score TMMi'!H22 -> PLANEJADO | I8: ='Score TMMi'!H35 -> PLANEJADO | J8: ='Score TMMi'!H48 -> PLANEJADO | K8: ='Score TMMi'!H61 -> PLANEJADO
B9: T1-N2-05 | C9: TRI 1 | D9: Engenharia de Qualidade | E9: N2 – Planejamento de Testes - Revisão | F9: QA / Produto / Squad | G9: ='Score TMMi'!H10 -> PLANEJADO | H9: ='Score TMMi'!H23 -> PLANEJADO | I9: ='Score TMMi'!H36 -> PLANEJADO | J9: ='Score TMMi'!H49 -> PLANEJADO | K9: ='Score TMMi'!H62 -> PLANEJADO
B10: T1-N2-N3-06 | C10: TRI 1 | D10: Engenharia de Qualidade | E10: N3 – Integração dos Testes ao SDLC N2 – Ambiente de Testes | F10: QA / Cloud / DevOps | G10: ='Score TMMi'!H12 -> PLANEJADO | H10: ='Score TMMi'!H25 -> PLANEJADO | I10: ='Score TMMi'!H38 -> PLANEJADO | J10: ='Score TMMi'!H51 -> ADOTADO | K10: ='Score TMMi'!H64 -> PLANEJADO
B11: T1-N2-07 | C11: TRI 1 | D11: Engenharia de Qualidade | E11: N2 – Desenho e Execução de Testes | F11: QA / QEs / Dev (apoio) | G11: ='Score TMMi'!H11 -> PLANEJADO | H11: ='Score TMMi'!H24 -> PLANEJADO | I11: ='Score TMMi'!H37 -> PLANEJADO | J11: ='Score TMMi'!H50 -> ADOTADO | K11: ='Score TMMi'!H63 -> PLANEJADO
B12: T1-N2-08 | C12: TRI 1 | D12: Engenharia de Qualidade | E12: N2 – Desenho e Execução de Testes | F12: QA / QEs / Dev (apoio) | G12: ='Score TMMi'!H13 -> PLANEJADO | H12: ='Score TMMi'!H26 -> PLANEJADO | I12: ='Score TMMi'!H39 -> PLANEJADO | J12: ='Score TMMi'!H52 -> ADOTADO | K12: ='Score TMMi'!H65 -> PLANEJADO
B13: T1-N2-09 | C13: TRI 1 | D13: Engenharia de Qualidade | E13: N2 – Desenho e Execução N2 – Monitoramento e Controle | F13: QA | G13: ='Score TMMi'!H14 -> PLANEJADO | H13: ='Score TMMi'!H27 -> PLANEJADO | I13: ='Score TMMi'!H40 -> PLANEJADO | J13: ='Score TMMi'!H53 -> ADOTADO | K13: ='Score TMMi'!H66 -> PLANEJADO
B14: T1-N3-10 | C14: TRI 1 | D14: Engenharia de Qualidade | E14: N3 – Revisões Técnicas | F14: QA / Produto / Squad | G14: ='Score TMMi'!H15 -> EM ADOÇÃO | H14: ='Score TMMi'!H28 -> EM ADOÇÃO | I14: ='Score TMMi'!H41 -> PLANEJADO | J14: ='Score TMMi'!H54 -> PLANEJADO | K14: ='Score TMMi'!H67 -> PLANEJADO
B15: T1-N2-N3-11 | C15: TRI 1 | D15: Engenharia de Qualidade | E15: N2 – Desenho e Execução N3 – Integração SDLC | F15: QA / QEs / Dev (apoio) | G15: ='Score TMMi'!H16 -> PLANEJADO | H15: ='Score TMMi'!H29 -> PLANEJADO | I15: ='Score TMMi'!H42 -> PLANEJADO | J15: ='Score TMMi'!H55 -> ADOTADO | K15: ='Score TMMi'!H68 -> PLANEJADO
B16: T1-N3-12 | C16: TRI 1 | D16: Engenharia de Qualidade | E16: N3 – Testes Não Funcionais | F16: QA (NFR) / Cloud / Produto / Tech Leads | G16: ='Score TMMi'!H17 -> PLANEJADO | H16: ='Score TMMi'!H30 -> PLANEJADO | I16: ='Score TMMi'!H43 -> EM ADOÇÃO | J16: ='Score TMMi'!H56 -> PLANEJADO | K16: ='Score TMMi'!H69 -> PLANEJADO
B17: T1-N3-13 | C17: TRI 1 | D17: Engenharia de Qualidade | E17: N3 – Testes Não Funcionais (piloto) N3 – Integração ao SDLC | F17: QA (NFR) / Cloud / DevOps | G17: ='Score TMMi'!H18 -> PLANEJADO | H17: ='Score TMMi'!H31 -> PLANEJADO | I17: ='Score TMMi'!H44 -> PLANEJADO | J17: ='Score TMMi'!H57 -> PLANEJADO | K17: ='Score TMMi'!H70 -> PLANEJADO
B18: T2-N2-N3-01 | C18: TRI 2 | D18: Engenharia de Qualidade | E18: N3 – Organização de Teste N2 – Planejamento | F18: QA / Produto | G18: NÃO INICIADO | H18: NÃO INICIADO | I18: NÃO INICIADO | J18: NÃO INICIADO | K18: NÃO INICIADO
B19: T2-N2-N3-02 | C19: TRI 2 | D19: Engenharia de Qualidade | E19: N3 – Integração ao SDLC N2 – Ambiente de Testes | F19: QA / Cloud / DevOps | G19: NÃO INICIADO | H19: NÃO INICIADO | I19: NÃO INICIADO | J19: NÃO INICIADO | K19: NÃO INICIADO
B20: T2-N3-03 | C20: TRI 2 | D20: Engenharia de Qualidade | E20: N3 – Testes Não Funcionais | F20: QA (NFR) / Produto / Tech Leads | G20: NÃO INICIADO | H20: NÃO INICIADO | I20: NÃO INICIADO | J20: NÃO INICIADO | K20: NÃO INICIADO
B21: T2-N3-04 | C21: TRI 2 | D21: Engenharia de Qualidade | E21: N3 – Programa de Treinamento em Testes | F21: QA / Gestão | G21: NÃO INICIADO | H21: NÃO INICIADO | I21: NÃO INICIADO | J21: NÃO INICIADO | K21: NÃO INICIADO
B22: T3-N4-01 | C22: TRI 3 | D22: Engenharia de Qualidade | E22: N4 – Avaliação da Qualidade do Produto (início) N4 – Medição (Incidentes × falhas) | F22: QA / Gestão | G22: NÃO INICIADO | H22: NÃO INICIADO | I22: NÃO INICIADO | J22: NÃO INICIADO | K22: NÃO INICIADO
B23: T3-N3-N4-02 | C23: TRI 3 | D23: Engenharia de Qualidade | E23: N4 – Medição N3 – Organização | F23: QA / Produto | G23: NÃO INICIADO | H23: NÃO INICIADO | I23: NÃO INICIADO | J23: NÃO INICIADO | K23: NÃO INICIADO
B24: T3-N4-03 | C24: TRI 3 | D24: Engenharia de Qualidade | E24: N4 – Medição dos Testes | F24: QA (NFR) / Gestão / Tech Leads | G24: NÃO INICIADO | H24: NÃO INICIADO | I24: NÃO INICIADO | J24: NÃO INICIADO | K24: NÃO INICIADO
B25: T4-N2-N3-01 | C25: TRI 4 | D25: Engenharia de Qualidade | E25: N2 – Política/Estratégia N3 – Organização | F25: QA / Cloud / Engenharia | G25: NÃO INICIADO | H25: NÃO INICIADO | I25: NÃO INICIADO | J25: NÃO INICIADO | K25: NÃO INICIADO
B26: T4-N5-02 | C26: TRI 4 | D26: Engenharia de Qualidade | E26: N5 – Prevenção de Defeitos | F26: QA / Squad / Gestão | G26: NÃO INICIADO | H26: NÃO INICIADO | I26: NÃO INICIADO | J26: NÃO INICIADO | K26: NÃO INICIADO
B27: T4-N4-03 | C27: TRI 4 | D27: Engenharia de Qualidade | E27: N4 – Medição dos Testes | F27: QA / Gestão | G27: NÃO INICIADO | H27: NÃO INICIADO | I27: NÃO INICIADO | J27: NÃO INICIADO | K27: NÃO INICIADO

Sheet ANUAL - Roadmap por Squads
A1: ID Melhoria | B1: Trimestre | C1: Fase | D1: Squad | E1: Entrega | F1: TMMi (Nível – Área) | G1: Envolvidos | H1: Evidência / DOR (Definition of Ready) | I1: Status Geral | J1: Responsável
A2: T1-N2-N3-01 | B2: TRI 1 | C2: Engenharia e Governança | D2: Todas (TAG) | E2: (MVP) Governança mínima de STG (regras, janelas, massa e auditoria) | F2: N2 – Ambiente de Testes / N3 – Organização de Testes | G2: Cloud / Engenharia / QA / Tech Leads | H2: Regras publicadas + controle de acesso + janelas definidas + procedimento de restauração de massa + registro/auditoria (quem/quando/o quê) | I2: Planejado | J2: Cloud + QA Chapter
A3: T1-N2-02 | B3: TRI 1 | C3: QA (Governança) | D3: Todas (TAG) | E3: (MVP) Política de Testes “Lite” (1 página) | F3: N2 – Política de Testes | G3: QA / Gestão | H3: Documento publicado (escopo, papéis, critérios mínimos, evidência mínima, compliance) + comunicação oficial | I3: Planejado | J3: QA Chapter
A4: T1-N2-N4-03 | B4: TRI 1 | C4: Melhoria Contínua | D4: Todas (TAG) | E4: (MVP) Indicadores comparáveis (baseline + tendência) + 3 gatilhos de ação | F4: N4 – Medição dos Testes (início) / N2 – Monitoramento e Controle | G4: QA / Gestão | H4: Dashboard publicado + definições + tendência trimestral + gatilhos e ações padrão documentados | I4: Planejado | J4: QA Chapter
A5: T1-N2-04 | B5: TRI 1 | C5: Engenharia de Qualidade | D5: Todas exceto: Plataforma (Cartões) e Consent+Interop (Duplicatas) | E5: (MVP) Levantar testes prioritários por risco por squad (P1/P2/P3) e registrar no Azure | F5: N2 – Planejamento de Testes | G5: QA / Produto / Squad | H5: Lista dos testes de regressão priorizados P1/P2/P3 no Azure + critério de priorização | I5: Planejado | J5: QAs por squad + Produto
A6: T1-N2-05 | B6: TRI 1 | C6: Engenharia de Qualidade | D6: Plataforma (Cartões) + Consent e Interop (Duplicatas) | E6: (MVP) Revisar P1/P2/P3 existente (sanidade e atualização mínima) | F6: N2 – Planejamento de Testes | G6: QA / Produto / Squad | H6: Revisão registrada (data) + ajustes se necessário + link no Azure | I6: Planejado | J6: QAs dessas squads + Produto
A7: T1-N2-N3-06 | B7: TRI 1 | C7: QA + Cloud | D7: Cartões + Duplicatas | E7: (MVP) Rodar automação em pipeline (template padrão replicável) para regressão P1 | F7: N3 – Integração dos Testes ao SDLC / N2 – Ambiente de Testes | G7: QA / Cloud / DevOps | H7: Pipeline rodando + gatilho definido + artefatos (report/log) + doc mínima | I7: Planejado | J7: Trombeta + Cloud
A8: T1-N2-07 | B8: TRI 1 | C8: Engenharia de Qualidade | D8: Cartões (todas as squads) exceto Plataforma | E8: (MVP) Migrar 20% dos testes automatizados do Robot para Playwright (baseline Q1, priorização por risco) | F8: N2 – Desenho e Execução de Testes | G8: QA / QEs / Dev (apoio) | H8: Baseline Robot (data de corte) + lista migrada + evidência de execução; foco preferencial em P1 | I8: Planejado | J8: QAs Cartões Anselmo
A9: T1-N2-08 | B9: TRI 1 | C9: Engenharia de Qualidade | D9: Cartões + Duplicatas (onde aplicável) | E9: (MVP) Automatizar o mínimo viável de P1 no Playwright por squad (regressão crítica) | F9: N2 – Desenho e Execução de Testes | G9: QA / QEs / Dev (apoio) | H9: Suites P1 + report/log + padrão de código aplicado + rastreio com PBI/Plano | I9: Planejado | J9: QAs por squad
A10: T1-N2-09 | B10: TRI 1 | C10: Engenharia de Qualidade | D10: Todas (TAG) | E10: (Aplicado via Playwright) Evidência padronizada de execução (report/log) | F10: N2 – Desenho e Execução / N2 – Monitoramento e Controle | G10: QA | H10: Evidência já gerada nos reports do Playwright e anexada/armazenada conforme padrão do repo/pipeline | I10: Adotado | J10: QAs (via padrão Playwright)
A11: T1-N3-10 | B11: TRI 1 | C11: Engenharia de Qualidade | D11: Duplicatas (Interop + Negotiation) | E11: (MVP) Qualidade do PBI: manter média ≥3 no Q1 (campo oficial) | F11: N3 – Revisões Técnicas (Quality Review) | G11: QA / Produto / Squad | H11: Rubrica/checklist por PBI + relatório mensal com média ≥3 | I11: Planejado | J11: André + Trombeta
A12: T1-N2-N3-11 | B12: TRI 1 | C12: Engenharia de Qualidade | D12: Duplicatas (Interop + Negotiation) | E12: (Stretch – faseado internamente) Avançar cobertura de regressão automatizada dos endpoints críticos (baseline Q1) | F12: N2 – Desenho e Execução / N3 – Integração SDLC | G12: QA / QEs / Dev (apoio) | H12: Baseline endpoints críticos datado + mapeamento endpoint→teste + evolução mensal comprovada por execução em pipeline | I12: Planejado | J12: André + Trombeta
... A25: T4-N4-03 | B25: TRI 4 | C25: Gestão | D25: Produtos: Cartões + Duplicatas | E25: Relatório executivo anual orientado por dados (incluindo NFR) | F25: N4 – Medição dos Testes | G25: QA / Gestão | H25: Relatório anual com tendências, decisões tomadas e próximos focos | I25: Planejado | J25: QA Chapter

Sheet Score TMMi
A1: Score TMMi - TRIMESTRE 1 | J1: Legenda
A3: SQUAD | B3: ID_MELHORIA | C3: NÍVEL E ÁREA DE PROCESSO | D3: ENTREGÁVEL | E3: DOR (DEFINITION OF DONE) | F3: EVIDÊNCIAS | G3: SCORE | H3: STATUS | J3: SCORE | K3: STATUS
A4: TODAS AS SQUADS | B4: T1-N2-02 | C4: N2 – Política de Testes | D4: (MVP) Política de Testes “Lite” (1 página) | E4: Documento publicado (escopo, papéis, critérios mínimos, evidência mínima, compliance) + comunicação oficial | F4: Política de Testes – TAG IMF0 | G4: 1.5 | H4: =IF(G4=1,"PLANEJADO",IF(G4=1.5,"DESENVOLVENDO",IF(G4=2,"EM ADOÇÃO",IF(G4=3,"ADOTADO","")))) -> DESENVOLVENDO | J4: 1 | K4: PLANEJADO
B5: T1-N2-N4-03 | C5: N4 – Medição dos Testes (início) N2 – Monitoramento e Controle | D5: (MVP) Indicadores comparáveis (baseline + tendência) + 3 gatilhos de ação | E5: Dashboard publicado + definições + tendência trimestral + gatilhos e ações padrão documentados | G5: 1.5 | H5: =IF(G5=1,"PLANEJADO",IF(G5=1.5,"DESENVOLVENDO",IF(G5=2,"EM ADOÇÃO",IF(G5=3,"ADOTADO","")))) -> DESENVOLVENDO | J5: 46143 | K5: DESENVOLVENDO
J6: 2 | K6: EM ADOÇÃO
A7: SQUAD | B7: ID_MELHORIA | C7: NÍVEL E ÁREA DE PROCESSO | D7: ENTREGÁVEL | E7: DOR (DEFINITION OF DONE) | F7: EVIDÊNCIAS | G7: SCORE | H7: STATUS | J7: 3 | K7: ADOTADO
A8: ATIVOS | B8: T1-N2-N3-01 | C8: N2 – Ambiente de Testes N3 – Organização de Testes | D8: (MVP) Governança mínima de STG (regras, janelas, massa e auditoria) | E8: Regras publicadas + controle de acesso + janelas definidas + procedimento de restauração de massa + registro/auditoria (quem/quando/o quê) | G8: 1 | H8: =IF(G8=1,"PLANEJADO",IF(G8=1.5,"DESENVOLVENDO",IF(G8=2,"EM ADOÇÃO",IF(G8=3,"ADOTADO","")))) -> PLANEJADO
B9: T1-N2-04 | C9: N2 – Planejamento de Testes - Levantamento | D9: (MVP) Levantar testes prioritários por risco por squad (P1/P2/P3) e registrar no Azure | E9: Lista dos testes de regressão priorizados P1/P2/P3 no Azure + critério de priorização | G9: 1 | H9: =IF(G9=1,"PLANEJADO",IF(G9=1.5,"DESENVOLVENDO",IF(G9=2,"EM ADOÇÃO",IF(G9=3,"ADOTADO","")))) -> PLANEJADO
B10: T1-N2-05 | C10: N2 – Planejamento de Testes - Revisão | D10: (MVP) Revisar P1/P2/P3 existente (sanidade e atualização mínima) | E10: Revisão registrada (data) + ajustes se necessário + link no Azure | G10: 1 | H10: =IF(G10=1,"PLANEJADO",IF(G10=1.5,"DESENVOLVENDO",IF(G10=2,"EM ADOÇÃO",IF(G10=3,"ADOTADO","")))) -> PLANEJADO
B11: T1-N2-07 | C11: N2 – Desenho e Execução de Testes | D11: (MVP) Migrar 20% dos testes automatizados do Robot para Playwright (baseline Q1, priorização por risco) | E11: Baseline Robot (data de corte) + lista migrada + evidência de execução; foco preferencial em P1 | G11: 1 | H11: =IF(G11=1,"PLANEJADO",IF(G11=1.5,"DESENVOLVENDO",IF(G11=2,"EM ADOÇÃO",IF(G11=3,"ADOTADO","")))) -> PLANEJADO
B12: T1-N2-N3-06 | C12: N3 – Integração dos Testes ao SDLC N2 – Ambiente de Testes | D12: (MVP) Rodar automação em pipeline (template padrão replicável) para regressão P1 | E12: Pipeline rodando + gatilho definido + artefatos (report/log) + doc mínima | G12: 1 | H12: =IF(G12=1,"PLANEJADO",IF(G12=1.5,"DESENVOLVENDO",IF(G12=2,"EM ADOÇÃO",IF(G12=3,"ADOTADO","")))) -> PLANEJADO
B13: T1-N2-08 | C13: N2 – Desenho e Execução de Testes | D13: (MVP) Automatizar o mínimo viável de P1 no Playwright por squad (regressão crítica) | E13: Suites P1 + report/log + padrão de código aplicado + rastreio com PBI/Plano | G13: 1 | H13: =IF(G13=1,"PLANEJADO",IF(G13=1.5,"DESENVOLVENDO",IF(G13=2,"EM ADOÇÃO",IF(G13=3,"ADOTADO","")))) -> PLANEJADO
B14: T1-N2-09 | C14: N2 – Desenho e Execução N2 – Monitoramento e Controle | D14: (Aplicado via Playwright) Evidência padronizada de execução (report/log) | E14: Evidência já gerada nos reports do Playwright e anexada/armazenada conforme padrão do repo/pipeline | G14: 1 | H14: =IF(G14=1,"PLANEJADO",IF(G14=1.5,"DESENVOLVENDO",IF(G14=2,"EM ADOÇÃO",IF(G14=3,"ADOTADO","")))) -> PLANEJADO
B15: T1-N3-10 | C15: N3 – Revisões Técnicas | D15: (MVP) Qualidade do PBI: manter média ≥3 no Q1 (campo oficial) | E15: Rubrica/checklist por PBI + relatório mensal com média ≥3 | G15: 2 | H15: =IF(G15=1,"PLANEJADO",IF(G15=1.5,"DESENVOLVENDO",IF(G15=2,"EM ADOÇÃO",IF(G15=3,"ADOTADO","")))) -> EM ADOÇÃO
B16: T1-N2-N3-11 | C16: N2 – Desenho e Execução N3 – Integração SDLC | D16: (Stretch – faseado internamente) Avançar cobertura de regressão automatizada dos endpoints críticos (baseline Q1) | E16: Baseline endpoints críticos datado + mapeamento endpoint→teste + evolução mensal comprovada por execução em pipeline | G16: 1 | H16: =IF(G16=1,"PLANEJADO",IF(G16=1.5,"DESENVOLVENDO",IF(G16=2,"EM ADOÇÃO",IF(G16=3,"ADOTADO","")))) -> PLANEJADO
B17: T1-N3-12 | C17: N3 – Testes Não Funcionais | D17: (MVP) Estratégia NFR “Lite” por produto/jornada (o que medir, quando rodar, critérios e evidência) | E17: Documento Lite publicado + backlog NFR priorizado por risco + cadência definida | G17: 1 | H17: =IF(G17=1,"PLANEJADO",IF(G17=1.5,"DESENVOLVENDO",IF(G17=2,"EM ADOÇÃO",IF(G17=3,"ADOTADO","")))) -> PLANEJADO
B18: T1-N3-13 | C18: N3 – Testes Não Funcionais (piloto) N3 – Integração ao SDLC | D18: (Piloto) NFR em pipeline com baseline e evidência (evitar atuação reativa) - Cartões | E18: Pipeline NFR rodando + report versionado + baseline coletado (2–4 semanas) + registro de execução | G18: 1 | H18: =IF(G18=1,"PLANEJADO",IF(G18=1.5,"DESENVOLVENDO",IF(G18=2,"EM ADOÇÃO",IF(G18=3,"ADOTADO","")))) -> PLANEJADO
A20: SQUAD | B20: ID_MELHORIA | C20: NÍVEL E ÁREA DE PROCESSO | D20: ENTREGÁVEL | E20: DOR (DEFINITION OF DONE) | F20: EVIDÊNCIAS | G20: SCORE | H20: STATUS
A21: DEMONSTRAÇÕES | B21: T1-N2-N3-01 | C21: N2 – Ambiente de Testes N3 – Organização de Testes | D21: (MVP) Governança mínima de STG (regras, janelas, massa e auditoria) | E21: Regras publicadas + controle de acesso + janelas definidas + procedimento de restauração de massa + registro/auditoria (quem/quando/o quê) | G21: 1 | H21: =IF(G21=1,"PLANEJADO",IF(G21=1.5,"DESENVOLVENDO",IF(G21=2,"EM ADOÇÃO",IF(G21=3,"ADOTADO","")))) -> PLANEJADO
B22: T1-N2-04 | C22: N2 – Planejamento de Testes - Levantamento | D22: (MVP) Levantar testes prioritários por risco por squad (P1/P2/P3) e registrar no Azure | E22: Lista dos testes de regressão priorizados P1/P2/P3 no Azure + critério de priorização | G22: 1 | H22: =IF(G22=1,"PLANEJADO",IF(G22=1.5,"DESENVOLVENDO",IF(G22=2,"EM ADOÇÃO",IF(G22=3,"ADOTADO","")))) -> PLANEJADO
B23: T1-N2-05 | C23: N2 – Planejamento de Testes - Revisão | D23: (MVP) Revisar P1/P2/P3 existente (sanidade e atualização mínima) | E23: Revisão registrada (data) + ajustes se necessário + link no Azure | G23: 1 | H23: =IF(G23=1,"PLANEJADO",IF(G23=1.5,"DESENVOLVENDO",IF(G23=2,"EM ADOÇÃO",IF(G23=3,"ADOTADO","")))) -> PLANEJADO
B24: T1-N2-07 | C24: N2 – Desenho e Execução de Testes | D24: (MVP) Migrar 20% dos testes automatizados do Robot para Playwright (baseline Q1, priorização por risco) | E24: Baseline Robot (data de corte) + lista migrada + evidência de execução; foco preferencial em P1 | G24: 1 | H24: =IF(G24=1,"PLANEJADO",IF(G24=1.5,"DESENVOLVENDO",IF(G24=2,"EM ADOÇÃO",IF(G24=3,"ADOTADO","")))) -> PLANEJADO
B25: T1-N2-N3-06 | C25: N3 – Integração dos Testes ao SDLC N2 – Ambiente de Testes | D25: (MVP) Rodar automação em pipeline (template padrão replicável) para regressão P1 | E25: Pipeline rodando + gatilho definido + artefatos (report/log) + doc mínima | G25: 1 | H25: =IF(G25=1,"PLANEJADO",IF(G25=1.5,"DESENVOLVENDO",IF(G25=2,"EM ADOÇÃO",IF(G25=3,"ADOTADO","")))) -> PLANEJADO
B26: T1-N2-08 | C26: N2 – Desenho e Execução de Testes | D26: (MVP) Automatizar o mínimo viável de P1 no Playwright por squad (regressão crítica) | E26: Suites P1 + report/log + padrão de código aplicado + rastreio com PBI/Plano | G26: 1 | H26: =IF(G26=1,"PLANEJADO",IF(G26=1.5,"DESENVOLVENDO",IF(G26=2,"EM ADOÇÃO",IF(G26=3,"ADOTADO","")))) -> PLANEJADO
B27: T1-N2-09 | C27: N2 – Desenho e Execução N2 – Monitoramento e Controle | D27: (Aplicado via Playwright) Evidência padronizada de execução (report/log) | E27: Evidência já gerada nos reports do Playwright e anexada/armazenada conforme padrão do repo/pipeline | G27: 1 | H27: =IF(G27=1,"PLANEJADO",IF(G27=1.5,"DESENVOLVENDO",IF(G27=2,"EM ADOÇÃO",IF(G27=3,"ADOTADO","")))) -> PLANEJADO
B28: T1-N3-10 | C28: N3 – Revisões Técnicas | D28: (MVP) Qualidade do PBI: manter média ≥3 no Q1 (campo oficial) | E28: Rubrica/checklist por PBI + relatório mensal com média ≥3 | G28: 2 | H28: =IF(G28=1,"PLANEJADO",IF(G28=1.5,"DESENVOLVENDO",IF(G28=2,"EM ADOÇÃO",IF(G28=3,"ADOTADO","")))) -> EM ADOÇÃO
B29: T1-N2-N3-11 | C29: N2 – Desenho e Execução N3 – Integração SDLC | D29: (Stretch – faseado internamente) Avançar cobertura de regressão automatizada dos endpoints críticos (baseline Q1) | E29: Baseline endpoints críticos datado + mapeamento endpoint→teste + evolução mensal comprovada por execução em pipeline | G29: 1 | H29: =IF(G29=1,"PLANEJADO",IF(G29=1.5,"DESENVOLVENDO",IF(G29=2,"EM ADOÇÃO",IF(G29=3,"ADOTADO","")))) -> PLANEJADO
B30: T1-N3-12 | C30: N3 – Testes Não Funcionais | D30: (MVP) Estratégia NFR “Lite” por produto/jornada (o que medir, quando rodar, critérios e evidência) | E30: Documento Lite publicado + backlog NFR priorizado por risco + cadência definida | G30: 1 | H30: =IF(G30=1,"PLANEJADO",IF(G30=1.5,"DESENVOLVENDO",IF(G30=2,"EM ADOÇÃO",IF(G30=3,"ADOTADO","")))) -> PLANEJADO
B31: T1-N3-13 | C31: N3 – Testes Não Funcionais (piloto) N3 – Integração ao SDLC | D31: (Piloto) NFR em pipeline com baseline e evidência (evitar atuação reativa) - Cartões | E31: Pipeline NFR rodando + report versionado + baseline coletado (2–4 semanas) + registro de execução | G31: 1 | H31: =IF(G31=1,"PLANEJADO",IF(G31=1.5,"DESENVOLVENDO",IF(G31=2,"EM ADOÇÃO",IF(G31=3,"ADOTADO","")))) -> PLANEJADO
A33: SQUAD | B33: ID_MELHORIA | C33: NÍVEL E ÁREA DE PROCESSO | D33: ENTREGÁVEL | E33: DOR (DEFINITION OF DONE) | F33: EVIDÊNCIAS | G33: SCORE | H33: STATUS
A34: OPERAÇÕES | B34: T1-N2-N3-01 | C34: N2 – Ambiente de Testes N3 – Organização de Testes | D34: (MVP) Governança mínima de STG (regras, janelas, massa e auditoria) | E34: Regras publicadas + controle de acesso + janelas definidas + procedimento de restauração de massa + registro/auditoria (quem/quando/o quê) | G34: 1 | H34: =IF(G34=1,"PLANEJADO",IF(G34=1.5,"DESENVOLVENDO",IF(G34=2,"EM ADOÇÃO",IF(G34=3,"ADOTADO","")))) -> PLANEJADO
B35: T1-N2-04 | C35: N2 – Planejamento de Testes - Levantamento | D35: (MVP) Levantar testes prioritários por risco por squad (P1/P2/P3) e registrar no Azure | E35: Lista dos testes de regressão priorizados P1/P2/P3 no Azure + critério de priorização | G35: 1 | H35: =IF(G35=1,"PLANEJADO",IF(G35=1.5,"DESENVOLVENDO",IF(G35=2,"EM ADOÇÃO",IF(G35=3,"ADOTADO","")))) -> PLANEJADO
B36: T1-N2-05 | C36: N2 – Planejamento de Testes - Revisão | D36: (MVP) Revisar P1/P2/P3 existente (sanidade e atualização mínima) | E36: Revisão registrada (data) + ajustes se necessário + link no Azure | G36: 1 | H36: =IF(G36=1,"PLANEJADO",IF(G36=1.5,"DESENVOLVENDO",IF(G36=2,"EM ADOÇÃO",IF(G36=3,"ADOTADO","")))) -> PLANEJADO
B37: T1-N2-07 | C37: N2 – Desenho e Execução de Testes | D37: (MVP) Migrar 20% dos testes automatizados do Robot para Playwright (baseline Q1, priorização por risco) | E37: Baseline Robot (data de corte) + lista migrada + evidência de execução; foco preferencial em P1 | G37: 1 | H37: =IF(G37=1,"PLANEJADO",IF(G37=1.5,"DESENVOLVENDO",IF(G37=2,"EM ADOÇÃO",IF(G37=3,"ADOTADO","")))) -> PLANEJADO
B38: T1-N2-N3-06 | C38: N3 – Integração dos Testes ao SDLC N2 – Ambiente de Testes | D38: (MVP) Rodar automação em pipeline (template padrão replicável) para regressão P1 | E38: Pipeline rodando + gatilho definido + artefatos (report/log) + doc mínima | G38: 1 | H38: =IF(G38=1,"PLANEJADO",IF(G38=1.5,"DESENVOLVENDO",IF(G38=2,"EM ADOÇÃO",IF(G38=3,"ADOTADO","")))) -> PLANEJADO
B39: T1-N2-08 | C39: N2 – Desenho e Execução de Testes | D39: (MVP) Automatizar o mínimo viável de P1 no Playwright por squad (regressão crítica) | E39: Suites P1 + report/log + padrão de código aplicado + rastreio com PBI/Plano | G39: 1 | H39: =IF(G39=1,"PLANEJADO",IF(G39=1.5,"DESENVOLVENDO",IF(G39=2,"EM ADOÇÃO",IF(G39=3,"ADOTADO","")))) -> PLANEJADO
B40: T1-N2-09 | C40: N2 – Desenho e Execução N2 – Monitoramento e Controle | D40: (Aplicado via Playwright) Evidência padronizada de execução (report/log) | E40: Evidência já gerada nos reports do Playwright e anexada/armazenada conforme padrão do repo/pipeline | G40: 1 | H40: =IF(G40=1,"PLANEJADO",IF(G40=1.5,"DESENVOLVENDO",IF(G40=2,"EM ADOÇÃO",IF(G40=3,"ADOTADO","")))) -> PLANEJADO
B41: T1-N3-10 | C41: N3 – Revisões Técnicas | D41: (MVP) Qualidade do PBI: manter média ≥3 no Q1 (campo oficial) | E41: Rubrica/checklist por PBI + relatório mensal com média ≥3 | G41: 1 | H41: =IF(G41=1,"PLANEJADO",IF(G41=1.5,"DESENVOLVENDO",IF(G41=2,"EM ADOÇÃO",IF(G41=3,"ADOTADO","")))) -> PLANEJADO
B42: T1-N2-N3-11 | C42: N2 – Desenho e Execução N3 – Integração SDLC | D42: (Stretch – faseado internamente) Avançar cobertura de regressão automatizada dos endpoints críticos (baseline Q1) | E42: Baseline endpoints críticos datado + mapeamento endpoint→teste + evolução mensal comprovada por execução em pipeline | G42: 1 | H42: =IF(G42=1,"PLANEJADO",IF(G42=1.5,"DESENVOLVENDO",IF(G42=2,"EM ADOÇÃO",IF(G42=3,"ADOTADO","")))) -> PLANEJADO
B43: T1-N3-12 | C43: N3 – Testes Não Funcionais | D43: (MVP) Estratégia NFR “Lite” por produto/jornada (o que medir, quando rodar, critérios e evidência) | E43: Documento Lite publicado + backlog NFR priorizado por risco + cadência definida | G43: 2 | H43: =IF(G43=1,"PLANEJADO",IF(G43=1.5,"DESENVOLVENDO",IF(G43=2,"EM ADOÇÃO",IF(G43=3,"ADOTADO","")))) -> EM ADOÇÃO
...
