Workbook

Sheet TMMi - Visão Institucional
B2: Visão do TMMi a nível organizacional
B3: Nível TMMi | C3: Área de Processo | D3: Status Institucional | E3: Observação
B4: Nível 2 | C4: Política e Estratégia de Testes | D4: Desenvolvendo | E4: Em construção; aplicada na prática, não formalizada
C5: Planejamento de Testes | D5: Adotado | E5: Modelo definido e replicável
C6: Monitoramento e Controle dos Testes | D6: Adotado | E6: Métricas e acompanhamento existentes
C7: Desenho e Execução de Testes | D7: Adotado | E7: Padrões e evidências definidos
C8: Gerenciamento de Defeitos | D8: Adotado | E8: Fluxo institucionalizado
C9: Ambiente de Testes | D9: Adotado | E9: Já existe o ambiente de STG
B10: Nível 3 | C10: Organização de Testes | D10: Em Adoção | E10: Chapter estruturado
C11: Programa de Treinamento em Testes | D11: Em Adoção | E11: Conteúdos e práticas existentes
C12: Integração dos Testes ao SDLC | D12: Em Adoção | E12: Quality Review e upstream parcial
C13: Testes Não Funcionais | D13: Desenvolvendo | E13: Iniciativas pontuais
C14: Revisões Técnicas (Quality Review) | D14: Adotado | E14: Prática definida e replicável
B15: Nível 4 | C15: Medição dos Testes | D15: Em Adoção | E15: As medições virão por consequencia, após melhorias acima
C16: Avaliação da Qualidade do Produto | D16: Em Adoção
C17: Revisões Avançadas | D17: Não Iniciado
B18: Nível 5 | C18: Prevenção de Defeitos | D18: Não Iniciado
C19: Controle da Qualidade | D19: Não Iniciado
C20: Otimização do Processo de Testes | D20: Não Iniciado

Sheet TMMi - Visão Squads
B2: Visão 2026 - Atualizada
B3: ID MELHORIA | C3: Trimestre | D3: Fase | E3: Nível e Área de Processo | F3: Envolvidos | G3: Squads Cartões | K3: Squads Duplicatas
G4: Ativos | H4: Demonstrações | I4: Operações | J4: Plataforma | K4: Interop | L4: Negotiation | M4: Consent
B5: T1-N2-N3-01 | C5: TRI 1 | D5: Engenharia de Qualidade | E5: N2 – Ambiente de Testes N3 – Organização de Testes | F5: Cloud / Engenharia / QA / Tech Leads | G5: ='Score TMMi'!H8 -> PLANEJADO | H5: ='Score TMMi'!H21 -> PLANEJADO | I5: ='Score TMMi'!H34 -> PLANEJADO | J5: ='Score TMMi'!H47 -> PLANEJADO | K5: ='Score TMMi'!H60 -> PLANEJADO | L5: ='Score TMMi'!H73 -> PLANEJADO | M5: ='Score TMMi'!H86 -> PLANEJADO
B6: T1-N2-02 | C6: TRI 1 | D6: Engenharia de Qualidade | E6: N2 – Política de Testes | F6: QA / Gestão | G6: ='Score TMMi'!H4 -> DESENVOLVENDO | H6: ='Score TMMi'!H4 -> DESENVOLVENDO | I6: ='Score TMMi'!H4 -> DESENVOLVENDO | J6: ='Score TMMi'!H4 -> DESENVOLVENDO | K6: ='Score TMMi'!H4 -> DESENVOLVENDO | L6: ='Score TMMi'!H4 -> DESENVOLVENDO | M6: ='Score TMMi'!H4 -> DESENVOLVENDO
B7: T1-N2-N4-03 | C7: TRI 1 | D7: Engenharia de Qualidade | E7: N4 – Medição dos Testes N2 – Monitoramento e Controle | F7: QA / Gestão | G7: ='Score TMMi'!H5 -> DESENVOLVENDO | H7: ='Score TMMi'!H5 -> DESENVOLVENDO | I7: ='Score TMMi'!H5 -> DESENVOLVENDO | J7: ='Score TMMi'!H5 -> DESENVOLVENDO | K7: ='Score TMMi'!H5 -> DESENVOLVENDO | L7: ='Score TMMi'!H5 -> DESENVOLVENDO | M7: ='Score TMMi'!H5 -> DESENVOLVENDO
B8: T1-N2-04 | C8: TRI 1 | D8: Engenharia de Qualidade | E8: N2 – Planejamento de Testes - Levantamento | F8: QA / Produto / Squad | G8: ='Score TMMi'!H10 -> PLANEJADO | H8: ='Score TMMi'!H22 -> PLANEJADO | I8: ='Score TMMi'!H35 -> PLANEJADO | J8: ='Score TMMi'!H48 -> PLANEJADO | K8: ='Score TMMi'!H61 -> PLANEJADO | L8: ='Score TMMi'!H74 -> PLANEJADO | M8: ='Score TMMi'!H87 -> PLANEJADO
B9: T1-N2-05 | C9: TRI 1 | D9: Engenharia de Qualidade | E9: N2 – Planejamento de Testes - Revisão | F9: QA / Produto / Squad | G9: ='Score TMMi'!H10 -> PLANEJADO | H9: ='Score TMMi'!H23 -> PLANEJADO | I9: ='Score TMMi'!H36 -> PLANEJADO | J9: ='Score TMMi'!H49 -> PLANEJADO | K9: ='Score TMMi'!H62 -> PLANEJADO | L9: ='Score TMMi'!H75 -> PLANEJADO | M9: ='Score TMMi'!H88 -> PLANEJADO
B10: T1-N2-N3-06 | C10: TRI 1 | D10: Engenharia de Qualidade | E10: N3 – Integração dos Testes ao SDLC N2 – Ambiente de Testes | F10: QA / Cloud / DevOps | G10: ='Score TMMi'!H12 -> PLANEJADO | H10: ='Score TMMi'!H25 -> PLANEJADO | I10: ='Score TMMi'!H38 -> PLANEJADO | J10: ='Score TMMi'!H51 -> PLANEJADO | K10: ='Score TMMi'!H64 -> PLANEJADO | L10: ='Score TMMi'!H77 -> PLANEJADO | M10: ='Score TMMi'!H90 -> PLANEJADO
B11: T1-N2-07 | C11: TRI 1 | D11: Engenharia de Qualidade | E11: N2 – Desenho e Execução de Testes | F11: QA / QEs / Dev (apoio) | G11: ='Score TMMi'!H11 -> PLANEJADO | H11: ='Score TMMi'!H24 -> PLANEJADO | I11: ='Score TMMi'!H37 -> PLANEJADO | J11: ='Score TMMi'!H50 -> PLANEJADO | K11: ='Score TMMi'!H63 -> PLANEJADO | L11: ='Score TMMi'!H76 -> PLANEJADO | M11: ='Score TMMi'!H89 -> PLANEJADO
B12: T1-N2-08 | C12: TRI 1 | D12: Engenharia de Qualidade | E12: N2 – Desenho e Execução de Testes | F12: QA / QEs / Dev (apoio) | G12: ='Score TMMi'!H13 -> PLANEJADO | H12: ='Score TMMi'!H26 -> PLANEJADO | I12: ='Score TMMi'!H39 -> PLANEJADO | J12: ='Score TMMi'!H52 -> PLANEJADO | K12: ='Score TMMi'!H65 -> PLANEJADO | L12: ='Score TMMi'!H78 -> PLANEJADO | M12: ='Score TMMi'!H91 -> PLANEJADO
B13: T1-N2-09 | C13: TRI 1 | D13: Engenharia de Qualidade | E13: N2 – Desenho e Execução N2 – Monitoramento e Controle | F13: QA | G13: ='Score TMMi'!H14 -> PLANEJADO | H13: ='Score TMMi'!H27 -> PLANEJADO | I13: ='Score TMMi'!H40 -> PLANEJADO | J13: ='Score TMMi'!H53 -> PLANEJADO | K13: ='Score TMMi'!H66 -> PLANEJADO | L13: ='Score TMMi'!H79 -> PLANEJADO | M13: ='Score TMMi'!H92 -> PLANEJADO
B14: T1-N3-10 | C14: TRI 1 | D14: Engenharia de Qualidade | E14: N3 – Revisões Técnicas | F14: QA / Produto / Squad | G14: ='Score TMMi'!H15 -> PLANEJADO | H14: ='Score TMMi'!H28 -> PLANEJADO | I14: ='Score TMMi'!H41 -> PLANEJADO | J14: ='Score TMMi'!H54 -> PLANEJADO | K14: ='Score TMMi'!H67 -> PLANEJADO | L14: ='Score TMMi'!H80 -> PLANEJADO | M14: ='Score TMMi'!H93 -> PLANEJADO
B15: T1-N2-N3-11 | C15: TRI 1 | D15: Engenharia de Qualidade | E15: N2 – Desenho e Execução N3 – Integração SDLC | F15: QA / QEs / Dev (apoio) | G15: ='Score TMMi'!H16 -> PLANEJADO | H15: ='Score TMMi'!H29 -> PLANEJADO | I15: ='Score TMMi'!H42 -> PLANEJADO | J15: ='Score TMMi'!H55 -> PLANEJADO | K15: ='Score TMMi'!H68 -> PLANEJADO | L15: ='Score TMMi'!H81 -> PLANEJADO | M15: ='Score TMMi'!H94 -> PLANEJADO
B16: T1-N3-12 | C16: TRI 1 | D16: Engenharia de Qualidade | E16: N3 – Testes Não Funcionais | F16: QA (NFR) / Cloud / Produto / Tech Leads | G16: ='Score TMMi'!H17 -> PLANEJADO | H16: ='Score TMMi'!H30 -> PLANEJADO | I16: ='Score TMMi'!H43 -> PLANEJADO | J16: ='Score TMMi'!H56 -> PLANEJADO | K16: ='Score TMMi'!H69 -> PLANEJADO | L16: ='Score TMMi'!H82 -> PLANEJADO | M16: ='Score TMMi'!H95 -> PLANEJADO
B17: T1-N3-13 | C17: TRI 1 | D17: Engenharia de Qualidade | E17: N3 – Testes Não Funcionais (piloto) N3 – Integração ao SDLC | F17: QA (NFR) / Cloud / DevOps | G17: ='Score TMMi'!H18 -> PLANEJADO | H17: ='Score TMMi'!H31 -> PLANEJADO | I17: ='Score TMMi'!H44 -> PLANEJADO | J17: ='Score TMMi'!H57 -> PLANEJADO | K17: ='Score TMMi'!H70 -> PLANEJADO | L17: ='Score TMMi'!H83 -> PLANEJADO | M17: ='Score TMMi'!H96 -> PLANEJADO
B18: T2-N2-N3-01 | C18: TRI 2 | D18: Engenharia de Qualidade | E18: N3 – Organização de Teste N2 – Planejamento | F18: QA / Produto | G18: NÃO INICIADO | H18: NÃO INICIADO | I18: NÃO INICIADO | J18: NÃO INICIADO | K18: NÃO INICIADO | L18: NÃO INICIADO | M18: NÃO INICIADO
B19: T2-N2-N3-02 | C19: TRI 2 | D19: Engenharia de Qualidade | E19: N3 – Integração ao SDLC N2 – Ambiente de Testes | F19: QA / Cloud / DevOps | G19: NÃO INICIADO | H19: NÃO INICIADO | I19: NÃO INICIADO | J19: NÃO INICIADO | K19: NÃO INICIADO | L19: NÃO INICIADO | M19: NÃO INICIADO
B20: T2-N3-03 | C20: TRI 2 | D20: Engenharia de Qualidade | E20: N3 – Testes Não Funcionais | F20: QA (NFR) / Produto / Tech Leads | G20: NÃO INICIADO | H20: NÃO INICIADO | I20: NÃO INICIADO | J20: NÃO INICIADO | K20: NÃO INICIADO | L20: NÃO INICIADO | M20: NÃO INICIADO
B21: T2-N3-04 | C21: TRI 2 | D21: Engenharia de Qualidade | E21: N3 – Programa de Treinamento em Testes | F21: QA / Gestão | G21: NÃO INICIADO | H21: NÃO INICIADO | I21: NÃO INICIADO | J21: NÃO INICIADO | K21: NÃO INICIADO | L21: NÃO INICIADO | M21: NÃO INICIADO
B22: T3-N4-01 | C22: TRI 3 | D22: Engenharia de Qualidade | E22: N4 – Avaliação da Qualidade do Produto (início) N4 – Medição (Incidentes × falhas) | F22: QA / Gestão | G22: NÃO INICIADO | H22: NÃO INICIADO | I22: NÃO INICIADO | J22: NÃO INICIADO | K22: NÃO INICIADO | L22: NÃO INICIADO | M22: NÃO INICIADO
B23: T3-N3-N4-02 | C23: TRI 3 | D23: Engenharia de Qualidade | E23: N4 – Medição N3 – Organização | F23: QA / Produto | G23: NÃO INICIADO | H23: NÃO INICIADO | I23: NÃO INICIADO | J23: NÃO INICIADO | K23: NÃO INICIADO | L23: NÃO INICIADO | M23: NÃO INICIADO
B24: T3-N4-03 | C24: TRI 3 | D24: Engenharia de Qualidade | E24: N4 – Medição dos Testes | F24: QA (NFR) / Gestão / Tech Leads | G24: NÃO INICIADO | H24: NÃO INICIADO | I24: NÃO INICIADO | J24: NÃO INICIADO | K24: NÃO INICIADO | L24: NÃO INICIADO | M24: NÃO INICIADO
B25: T4-N2-N3-01 | C25: TRI 4 | D25: Engenharia de Qualidade | E25: N2 – Política/Estratégia N3 – Organização | F25: QA / Cloud / Engenharia | G25: NÃO INICIADO | H25: NÃO INICIADO | I25: NÃO INICIADO | J25: NÃO INICIADO | K25: NÃO INICIADO | L25: NÃO INICIADO | M25: NÃO INICIADO
B26: T4-N5-02 | C26: TRI 4 | D26: Engenharia de Qualidade | E26: N5 – Prevenção de Defeitos | F26: QA / Squad / Gestão | G26: NÃO INICIADO | H26: NÃO INICIADO | I26: NÃO INICIADO | J26: NÃO INICIADO | K26: NÃO INICIADO | L26: NÃO INICIADO | M26: NÃO INICIADO
B27: T4-N4-03 | C27: TRI 4 | D27: Engenharia de Qualidade | E27: N4 – Medição dos Testes | F27: QA / Gestão | G27: NÃO INICIADO | H27: NÃO INICIADO | I27: NÃO INICIADO | J27: NÃO INICIADO | K27: NÃO INICIADO | L27: NÃO INICIADO | M27: NÃO INICIADO

Sheet Todos Trimestres TMMi - Visão S
B2: Visão 2026 - Atualizada
B3: Trimestre | C3: Fase | D3: Nível e Área de Processo | E3: Envolvidos | F3: Squads Cartões | J3: Squads Duplicatas
F4: Ativos | G4: Demonstrações | H4: Operações | I4: Plataforma | J4: Interop | K4: Negotiation | L4: Consent
B5: TRI 1 | C5: Engenharia de Qualidade | D5: N2 – Ambiente de Testes N3 – Organização de Testes | E5: Cloud / Engenharia / QA / Tech Leads | F5: Planejado | G5: Planejado | H5: Planejado | I5: Planejado | J5: Planejado | K5: Planejado | L5: Planejado
B6: TRI 1 | C6: Engenharia de Qualidade | D6: N2 – Política de Testes | E6: QA / Gestão | F6: Desenvolvendo | G6: Desenvolvendo | H6: Desenvolvendo | I6: Desenvolvendo | J6: Desenvolvendo | K6: Desenvolvendo | L6: Desenvolvendo
B7: TRI 1 | C7: Engenharia de Qualidade | D7: N4 – Medição dos Testes N2 – Monitoramento e Controle | E7: QA / Gestão | F7: Planejado | G7: Planejado | H7: Planejado | I7: Planejado | J7: Planejado | K7: Planejado | L7: Planejado
B8: TRI 1 | C8: Engenharia de Qualidade | D8: N2 – Planejamento de Testes - Levantamento | E8: QA / Produto / Squad | F8: Planejado | G8: Planejado | H8: Planejado | I8: Planejado | J8: Planejado | K8: Planejado | L8: Planejado
B9: TRI 1 | C9: Engenharia de Qualidade | D9: N2 – Planejamento de Testes - Revisão | E9: QA / Produto / Squad | F9: Planejado | G9: Planejado | H9: Planejado | I9: Planejado | J9: Planejado | K9: Planejado | L9: Planejado
B10: TRI 1 | C10: Engenharia de Qualidade | D10: N3 – Integração dos Testes ao SDLC N2 – Ambiente de Testes | E10: QA / Cloud / DevOps | F10: Planejado | G10: Planejado | H10: Planejado | I10: Planejado | J10: Planejado | K10: Planejado | L10: Planejado
B11: TRI 1 | C11: Engenharia de Qualidade | D11: N2 – Desenho e Execução de Testes | E11: QA / QEs / Dev (apoio) | F11: Planejado | G11: Planejado | H11: Planejado | I11: Planejado | J11: Planejado | K11: Planejado | L11: Planejado
B12: TRI 1 | C12: Engenharia de Qualidade | D12: N2 – Desenho e Execução de Testes | E12: QA / QEs / Dev (apoio) | F12: Planejado | G12: Planejado | H12: Planejado | I12: Planejado | J12: Planejado | K12: Planejado | L12: Planejado
B13: TRI 1 | C13: Engenharia de Qualidade | D13: N2 – Desenho e Execução N2 – Monitoramento e Controle | E13: QA | F13: Planejado | G13: Planejado | H13: Planejado | I13: Planejado | J13: Planejado | K13: Planejado | L13: Planejado
B14: TRI 1 | C14: Engenharia de Qualidade | D14: N3 – Revisões Técnicas | E14: QA / Produto / Squad | F14: Planejado | G14: Planejado | H14: Planejado | I14: Planejado | J14: Planejado | K14: Planejado | L14: Planejado
B15: TRI 1 | C15: Engenharia de Qualidade | D15: N2 – Desenho e Execução N3 – Integração SDLC | E15: QA / QEs / Dev (apoio) | F15: Planejado | G15: Planejado | H15: Planejado | I15: Planejado | J15: Planejado | K15: Planejado | L15: Planejado
B16: TRI 1 | C16: Engenharia de Qualidade | D16: N3 – Testes Não Funcionais | E16: QA (NFR) / Cloud / Produto / Tech Leads | F16: Planejado | G16: Planejado | H16: Planejado | I16: Planejado | J16: Planejado | K16: Planejado | L16: Planejado
... B28: TRI 4 | C28: Engenharia de Qualidade | D28: N4 – Medição dos Testes | E28: QA / Gestão | F28: Planejado | G28: Planejado | H28: Planejado | I28: Planejado | J28: Planejado | K28: Planejado | L28: Planejado
B33: Visão 2025
B34: Fase | C34: Nível e Área de Processo | D34: Envolvidos | E34: Squad Cartões | I34: Squad Duplicatas
E35: Ativos | F35: Demonstrações | G35: Operações | H35: Plataforma | I35: Interop | J35: Negotiation | K35: Consent
B36: Trabalho de Base | C36: N2 – Política de Testes | D36: Institucional | E36: Desenvolvendo | F36: Desenvolvendo | G36: Desenvolvendo | H36: Desenvolvendo | I36: Desenvolvendo | J36: Desenvolvendo | K36: Desenvolvendo
B37: Trabalho de Base | C37: N2 – Estratégia de Testes | D37: QA / Squads | E37: Adotado | F37: Adotado | G37: Em Adoção | H37: Adotado | I37: Adotado | J37: Adotado | K37: Adotado
B38: Trabalho de Base | C38: N2 – Planejamento de Testes | D38: QA / Produto | E38: Adotado | F38: Adotado | G38: Em Adoção | H38: Adotado | I38: Adotado | J38: Adotado | K38: Adotado
B39: Trabalho de Base | C39: N2 – Monitoramento e Controle dos Testes | D39: QA / Tech Lead | E39: Adotado | F39: Adotado | G39: Adotado | H39: Adotado | I39: Adotado | J39: Adotado | K39: Adotado
B40: Trabalho de Base | C40: N2 – Desenho e Execução de Testes | D40: QA | E40: Adotado | F40: Adotado | G40: Adotado | H40: Adotado | I40: Adotado | J40: Adotado | K40: Adotado
B41: Trabalho de Base | C41: N2 – Gerenciamento de Defeitos | D41: QA / Squad | E41: Adotado | F41: Adotado | G41: Adotado | H41: Adotado | I41: Adotado | J41: Adotado | K41: Adotado
B42: Trabalho de Base | C42: N2 – Ambiente de Testes | D42: QA / Cloud | E42: Não Aplicável | F42: Não Aplicável | G42: Não Aplicável | H42: Não Aplicável | I42: Não Aplicável | J42: Não Aplicável | K42: Não Aplicável
B43: Engenharia de Qualidade | C43: N3 – Organização de Testes | D43: QA / Gestão | E43: Em Adoção | F43: Em Adoção | G43: Desenvolvendo | H43: Adotado | I43: Adotado | J43: Em Adoção | K43: Adotado
B44: Engenharia de Qualidade | C44: N3 – Programa de Treinamento em Testes | D44: Institucional | E44: Em Adoção | F44: Em Adoção | G44: Em Adoção | H44: Em Adoção | I44: Em Adoção | J44: Em Adoção | K44: Em Adoção
B45: Engenharia de Qualidade | C45: N3 – Integração dos Testes ao SDLC | D45: QA / Produto / Dev | E45: Em Adoção | F45: Desenvolvendo | G45: Desenvolvendo | H45: Adotado | I45: Adotado | J45: Em Adoção | K45: Adotado
B46: Engenharia de Qualidade | C46: N3 – Testes Não Funcionais | D46: QA / Cloud / SI/ Arquitetura | E46: Planejado | F46: Em Adoção | G46: Em Adoção | H46: Planejado | I46: Planejado | J46: Planejado | K46: Desenvolvendo
B47: Engenharia de Qualidade | C47: N3 – Revisões Técnicas (Quality Review) | D47: QA / Produto | E47: Adotado | F47: Em Adoção | G47: Em Adoção | H47: Adotado | I47: Adotado | J47: Adotado | K47: Adotado
... B53: Engenharia de Qualidade | C53: N5 - Otimização do Processo de Testes | D53: QA / Gestão / Squads | E53: Não Iniciado | F53: Não Iniciado | G53: Não Iniciado | H53: Não Iniciado | I53: Não Iniciado | J53: Não Iniciado | K53: Não Iniciado

Sheet Roadmap Trimestral
B2: Trimestre | C2: Fase | D2: Entrega | E2: TMMi (Nível – Área) | F2: Envolvidos | G2: Evidência / Critério de pronto | H2: Status | I2: Responsável
B3: TRI 1 (Jan-Mar) | C3: Engenharia e Governança | D3: Governança de uso do STG (regras, permissões, janelas e proteção de dados/massa) | E3: N3 – Organização de Testes | F3: Engenharia/Cloud/QA/Tech Leads | G3: Política de uso do STG + controle de acessos + janelas de execução + procedimento de restauração de massa + trilha de auditoria (quem rodou o quê) | H3: Planejado | I3: Engenharia/Cloud + QA Chapter
C4: QA | D4: Iniciar Mapeamento TODAS as jornadas de testes (Robot → Playwright) | E4: N3 – Integração dos Testes ao SDLC | F4: QA / Squads | G4: Lista de jornadas por squad + matriz “jornada → cenários → testes → automação” + priorização por criticidade | H4: Planejado | I4: QA Chapter + QAs por squad
C5: QA | D5: Levantar os testes prioritários por squad (baseado em jornada + risco) | E5: N2 – Planejamento de Testes + N3 – Organização de Testes | F5: QA / Produto / Squad | G5: Escopo de testes prioritários por squad (P1/P2/P3 ou crítico/alto/médio) + link no Azure Test Plans | H5: Planejado | I5: QA + Produto
C6: QA | D6: Automatizar os testes prioritários no Playwright (mínimo viável por jornada) | E6: N2 – Desenho e Execução de Testes + N3 – Integração dos Testes ao SDLC | F6: QA / Dev (apoio) | G6: Suites Playwright criadas por jornada + evidência de execução + padrão de código aplicado | H6: Planejado | I6: QA + QEs
C7: QA + Cloud | D7: Integrar os testes automatizados à pipeline de QA (execução na nuvem) | E7: N3 – Integração dos Testes ao SDLC / N2 – Ambiente de Testes | F7: QA / Cloud / DevOps | G7: Pipeline rodando Playwright + artefatos (report/log) + gatilho por PR/merge/agenda (conforme definido) | H7: Planejado | I7: Cloud/DevOps + QA
C8: Melhoria Contínua | D8: Consolidar indicadores de adoção das melhorias (visão executiva) | E8: N4 – Medição dos Testes | F8: QA / Gestão | G8: Dashboard com indicadores definidos (ex.: adoção QR, cobertura de jornadas, execução/pipeline, defeitos críticos) | H8: Planejado | I8: QA Chapter
C9: Melhoria Contínua | D9: Implementar Engenharia de Qualidade com Testes Estáticos (em piloto) | E9: N3 – Revisões Técnicas (Quality Review) | F9: QA / Dev / Tech Lead | G9: Checklist + evidência de aplicação em refinamento/PRs (mínimo) + registro do que foi prevenido | H9: Despriorizado | I9: Trombeta + QA Chapter

Sheet Roadmap por Squad
B3: Trimestre | C3: Fase | D3: Squad | E3: Entrega | F3: TMMi (Nível – Área) | G3: Envolvidos | H3: Evidência / Critério de pronto | I3: Status | J3: Responsável
B4: TRI 1 | C4: Engenharia e Governança | D4: Todas | E4: Governança de uso do STG (regras, janelas, massa) | F4: N3 – Organização de Testes | G4: Engenharia / Cloud / QA | H4: Política STG + controle de acesso + trilha de auditoria | I4: Não Iniciado | J4: Cloud + QA Chapter
B5: TRI 1 | C5: QA | D5: Ativos | E5: Mapear 2 jornadas críticas | F5: N2 – Planejamento de Testes | G5: QA / Squad | H5: Jornadas documentadas + riscos | I5: Não Iniciado | J5: QA Squad
B6: TRI 1 | C6: QA | D6: Demonstrações | E6: Mapear 1 jornada crítica | F6: N2 – Planejamento de Testes | G6: QA / Squad | H6: Jornada documentada + riscos | I6: Não Iniciado | J6: QA Squad
B7: TRI 1 | C7: QA | D7: Operações | E7: Levantar jornada crítica + riscos | F7: N2 – Planejamento de Testes | G7: QA / Squad | H7: Escopo mínimo de testes críticos | I7: Não Iniciado | J7: QA Squad
B8: TRI 1 | C8: QA | D8: Interop | E8: Mapear 1 jornada crítica interop | F8: N2 – Planejamento de Testes | G8: QA / Squad | H8: Jornada interop documentada | I8: Não Iniciado | J8: QA Squad
B9: TRI 1 | C9: QA | D9: Negotiation | E9: Mapear 1 jornada crítica | F9: N2 – Planejamento de Testes | G9: QA / Squad | H9: Jornada documentada | I9: Não Iniciado | J9: QA Squad
B10: TRI 1 | C10: QA | D10: Ativos / Plataforma | E10: Automatizar 1 jornada crítica (mínimo viável) | F10: N2 Execução / N3 Integração SDLC | G10: QA / QEs | H10: Suite Playwright + evidência | I10: Não Iniciado | J10: QA + QEs
B11: TRI 1 | C11: QA | D11: Todas | E11: Levantar testes prioritários por risco | F11: N2 – Planejamento de Testes | G11: QA / Produto | H11: Escopo P1/P2/P3 no Azure | I11: Não Iniciado | J11: QA + Produto
B12: TRI 1 | C12: Melhoria Contínua | D12: Todas | E12: Consolidar indicadores | F12: N4 – Medição dos Testes | G12: QA / Gestão | H12: Dashboard simples (adoção / defeitos críticos) | I12: Não Iniciado | J12: QA Chapter
B15: Trimestre | C15: Fase | D15: Squad | E15: Entrega | F15: TMMi | G15: Envolvidos | H15: Evidência | I15: Status | J15: Responsável
B16: TRI 2 | C16: QA | D16: Cartões (cross) | E16: Consolidar jornadas por produto | F16: N3 – Organização de Testes | G16: QA / Produto | H16: Mapa consolidado | I16: Não Iniciado | J16: QA Chapter
... B34: TRI 4 | C34: Gestão | D34: Todas | E34: Consolidar visão executiva anual | F34: N4 – Medição | G34: QA / Gestão | H34: Relatório executivo | I34: Não Iniciado | J34: QA Chapter

Sheet OLD_Roadmap por Squads
A2: ID Melhoria | B2: Trimestre | C2: Squad | D2: Detalhe da Entrega | E2: TMMi (Nível – Área) | F2: Envolvidos | G2: Evidência / Critério de pronto | H2: Status | I2: Responsável
B3: TRI 1 | C3: Todas (TAG) | D3: Consolidar indicadores comparáveis (baseline + tendência) e gatilhos de ação | E3: N4 – Medição dos Testes (início) N2 – Monitoramento e Controle | F3: QA / Gestão | G3: Dashboard publicado + definição das métricas + tendência trimestral + 3 gatilhos e ações padrão | H3: Desenvolvendo | I3: QA Chapter
B4: TRI 1 | C4: Todas (TAG) | D4: Política de Testes “Lite” (1 página) | E4: N2 – Política de Testes | F4: QA / Gestão | G4: Documento publicado (escopo, papéis, critérios mínimos, evidência mínima, compliance) | H4: Desenvolvendo | I4: QA Chapter
B5: TRI 1 | C5: Todas exceto: Plataforma (Cartões) e Consent+Interop (Duplicatas) | D5: Levantar testes prioritários por risco por squad (P1/P2/P3) e registrar no Azure | E5: N2 – Planejamento de Testes | F5: QA / Produto / Squad | G5: Lista P1/P2/P3 no Azure + critério de priorização registrado + baseline datado | H5: Desenvolvendo | I5: QAs por squad + Produto
B6: TRI 1 | C6: Cartões (todas as squads exceto Plataforma) | D6: Migrar 20% dos testes automatizados do Robot para Playwright (baseline Q1) | E6: N2 – Desenho e Execução de Testes | F6: QA / QEs / Dev (apoio) | G6: Escopo com os testes + lista dos testes migrados Playwright + evidência de execução | H6: Não Iniciado | I6: QAs por squad
B7: TRI 1 | C7: Cartões + Duplicatas (onde aplicável) | D7: Automatizar P1 mínimo viável em Playwright por squad e gerar evidência | E7: N2 – Desenho e Execução de Testes | F7: QA / QEs / Dev (apoio) | G7: Suites Playwright P1 + report/log anexado + padrão aplicado | H7: Não Iniciado | I7: QAs por squad
B8: TRI 1 | C8: Cartões + Duplicatas | D8: Rodar automação em pipeline (padrão replicável + evidência) NF + NFT | E8: N3 – Integração dos Testes ao SDLC N2 – Ambiente de Testes | F8: QA / Cloud / DevOps | G8: Pipeline rodando + gatilho definido (PR/merge/agendado) + artefatos (report/log) + doc mínima | H8: Não Iniciado | I8: Trombeta + Cloud
B9: TRI 1 | C9: Duplicatas (Interop + Negotiation) | D9: Qualidade do PBI: manter média ≥3 no Q1 | E9: N3 – Revisões Técnicas (Quality Review) | F9: QA / Produto / Squad | G9: Checklist/rubrica por PBI + relatório mensal com média ≥3 | H9: Desenvolvendo | I9: QAs por squad
B10: TRI 1 | C10: Duplicatas (Interop + Negotiation) | D10: Cobertura: 85% da regressão funcional automatizada dos endpoints críticos (baseline Q1) | E10: N2 – Desenho e Execução N3 – Integração SDLC | F10: QA / QEs / Dev (apoio) | G10: Baseline endpoints críticos + mapeamento endpoint→teste + execução em pipeline + evidência | H10: Não Iniciado | I10: André + Trombeta
B11: TRI 1 | C11: QA + Cloud | D11: NFR piloto com critério e recorrência (não “para todos”) | E11: N3 – Testes Não Funcionais (piloto) | F11: QA / Cloud / SI (se aplicável) | G11: Critérios (threshold) + execução recorrente + evidência do resultado | H11: Não Iniciado | I11: Trombeta + Cloud
B17: TRI 1 | C17: Todas (TAG) | D17: Governança Mínima em STG | E17: N2 – Política/ Estratégia N2 – Ambiente / N3 – Organização | F17: QA / Cloud / Engenharia | G17: Versão mínima publicada com regras, janelas, massa e auditoria | H17: Não Iniciado | I17: QA Chapter + Cloud
B18: TRI 2 | C18: Todas (TAG) | D18: Escalar padrão (P1/P2/P3 + regressão mínima) para squads restantes e formalizar regressão por squad | E18: N3 – Organização de Testes N2 – Planejamento de Testes | F18: QA / Produto | G18: Regra de regressão por squad publicada + suites P1 padronizadas por squad | H18: Não Iniciado | I18: QA Chapter + QAs
B19: TRI 2 | C19: Todas (TAG) | D19: Estabilizar automação (reduzir flaky, padronizar massa/dados e asserções) | E19: N3 – Integração dos Testes ao SDLC / N2 – Ambiente de Testes | F19: QA / Cloud / DevOps | G19: Queda de falhas flakey + padrão de dados/massa + evidência de estabilidade em pipeline | H19: Não Iniciado | I19: QA Chapter + Cloud
... B26: TRI 4 | C26: Todas (TAG) | D26: Consolidar visão executiva anual orientada por dados | E26: N4 – Medição dos Testes | F26: QA / Gestão | G26: Relatório anual com tendências, decisões tomadas e próximos focos | H26: Não Iniciado | I26: QA Chapter

Sheet Score TMMi
A1: Score TMMi - TRIMESTRE 1 | J1: Legenda
A3: SQUAD | B3: ID_MELHORIA | C3: NÍVEL E ÁREA DE PROCESSO | D3: ENTREGÁVEL | E3: DOR (DEFINITION OF DONE) | F3: EVIDÊNCIAS | G3: SCORE | H3: STATUS | J3: SCORE | K3: STATUS
A4: TODAS AS SQUADS | B4: T1-N2-02 | C4: N2 – Política de Testes | D4: (MVP) Política de Testes “Lite” (1 página) | E4: Documento publicado (escopo, papéis, critérios mínimos, evidência mínima, compliance) + comunicação oficial | F4: Política de Testes – TAG IMF0 | G4: 1.5 | H4: =IF(G4=1,"PLANEJADO",IF(G4=1.5,"DESENVOLVENDO",IF(G4=2,"EM ADOÇÃO",IF(G4=3,"ADOTADO","")))) -> DESENVOLVENDO | J4: 1 | K4: PLANEJADO
B5: T1-N2-N4-03 | C5: N4 – Medição dos Testes (início) N2 – Monitoramento e Controle | D5: (MVP) Indicadores comparáveis (baseline + tendência) + 3 gatilhos de ação | E5: Dashboard publicado + definições + tendência trimestral + gatilhos e ações padrão documentados | G5: 1.5 | H5: =IF(G5=1,"PLANEJADO",IF(G5=1.5,"DESENVOLVENDO",IF(G5=2,"EM ADOÇÃO",IF(G5=3,"ADOTADO","")))) -> DESENVOLVENDO | J5: 46143 | K5: DESENVOLVENDO
J6: 2 | K6: EM ADOÇÃO
A7: SQUAD | B7: ID_MELHORIA | C7: NÍVEL E ÁREA DE PROCESSO | D7: ENTREGÁVEL | E7: DOR (DEFINITION OF DONE) | F7: EVIDÊNCIAS | G7: SCORE | H7: STATUS | J7: 3 | K7: ADOTADO
A8: ATIVOS | B8: T1-N2-N3-01 | C8: N2 – Ambiente de Testes N3 – Organização de Testes | D8: (MVP) Governança mínima de STG (regras, janelas, massa e auditoria) | E8: Regras publicadas + controle de acesso + janelas definidas + procedimento de restauração de massa + registro/auditoria (quem/quando/o quê) | G8: 1 | H8: =IF(G8=1,"PLANEJADO",IF(G8=1.5,"DESENVOLVENDO",IF(G8=2,"EM ADOÇÃO",IF(G8=3,"ADOTADO","")))) -> PLANEJADO
B9: T1-N2-04 | C9: N2 – Planejamento de Testes - Levantamento | D9: (MVP) Levantar testes prioritários por risco por squad (P1/P2/P3) e registrar no Azure | E9: Lista dos testes de regressão priorizados P1/P2/P3 no Azure + critério de priorização | G9: 1 | H9: =IF(G9=1,"PLANEJADO",IF(G9=1.5,"DESENVOLVENDO",IF(G9=2,"EM ADOÇÃO",IF(G9=3,"ADOTADO","")))) -> PLANEJADO
B10: T1-N2-05 | C10: N2 – Planejamento de Testes - Revisão | D10: (MVP) Revisar P1/P2/P3 existente (sanidade e atualização mínima) | E10: Revisão registrada (data) + ajustes se necessário + link no Azure | G10: 1 | H10: =IF(G10=1,"PLANEJADO",IF(G10=1.5,"DESENVOLVENDO",IF(G10=2,"EM ADOÇÃO",IF(G10=3,"ADOTADO","")))) -> PLANEJADO
B11: T1-N2-07 | C11: N2 – Desenho e Execução de Testes | D11: (MVP) Migrar 20% dos testes automatizados do Robot para Playwright (baseline Q1, priorização por risco) | E11: Baseline Robot (data de corte) + lista migrada + evidência de execução; foco preferencial em P1 | G11: 1 | H11: =IF(G11=1,"PLANEJADO",IF(G11=1.5,"DESENVOLVENDO",IF(G11=2,"EM ADOÇÃO",IF(G11=3,"ADOTADO","")))) -> PLANEJADO
B12: T1-N2-N3-06 | C12: N3 – Integração dos Testes ao SDLC N2 – Ambiente de Testes | D12: (MVP) Rodar automação em pipeline (template padrão replicável) para regressão P1 | E12: Pipeline rodando + gatilho definido + artefatos (report/log) + doc mínima | G12: 1 | H12: =IF(G12=1,"PLANEJADO",IF(G12=1.5,"DESENVOLVENDO",IF(G12=2,"EM ADOÇÃO",IF(G12=3,"ADOTADO","")))) -> PLANEJADO
B13: T1-N2-08 | C13: N2 – Desenho e Execução de Testes | D13: (MVP) Automatizar o mínimo viável de P1 no Playwright por squad (regressão crítica) | E13: Suites P1 + report/log + padrão de código aplicado + rastreio com PBI/Plano | G13: 1 | H13: =IF(G13=1,"PLANEJADO",IF(G13=1.5,"DESENVOLVENDO",IF(G13=2,"EM ADOÇÃO",IF(G13=3,"ADOTADO","")))) -> PLANEJADO
B14: T1-N2-09 | C14: N2 – Desenho e Execução N2 – Monitoramento e Controle | D14: (Aplicado via Playwright) Evidência padronizada de execução (report/log) | E14: Evidência já gerada nos reports do Playwright e anexada/armazenada conforme padrão do repo/pipeline | G14: 1 | H14: =IF(G14=1,"PLANEJADO",IF(G14=1.5,"DESENVOLVENDO",IF(G14=2,"EM ADOÇÃO",IF(G14=3,"ADOTADO","")))) -> PLANEJADO
B15: T1-N3-10 | C15: N3 – Revisões Técnicas | D15: (MVP) Qualidade do PBI: manter média ≥3 no Q1 (campo oficial) | E15: Rubrica/checklist por PBI + relatório mensal com média ≥3 | G15: 1 | H15: =IF(G15=1,"PLANEJADO",IF(G15=1.5,"DESENVOLVENDO",IF(G15=2,"EM ADOÇÃO",IF(G15=3,"ADOTADO","")))) -> PLANEJADO
B16: T1-N2-N3-11 | C16: N2 – Desenho e Execução N3 – Integração SDLC | D16: (Stretch – faseado internamente) Avançar cobertura de regressão automatizada dos endpoints críticos (baseline Q1) | E16: Baseline endpoints críticos datado + mapeamento endpoint→teste + evolução mensal comprovada por execução em pipeline | G16: 1 | H16: =IF(G16=1,"PLANEJADO",IF(G16=1.5,"DESENVOLVENDO",IF(G16=2,"EM ADOÇÃO",IF(G16=3,"ADOTADO","")))) -> PLANEJADO
B17: T1-N3-12 | C17: N3 – Testes Não Funcionais | D17: (MVP) Estratégia NFR “Lite” por produto/jornada (o que medir, quando rodar, critérios e evidência) | E17: Documento Lite publicado + backlog NFR priorizado por risco + cadência definida | G17: 1 | H17: =IF(G17=1,"PLANEJADO",IF(G17=1.5,"DESENVOLVENDO",IF(G17=2,"EM ADOÇÃO",IF(G17=3,"ADOTADO","")))) -> PLANEJADO
B18: T1-N3-13 | C18: N3 – Testes Não Funcionais (piloto) N3 – Integração ao SDLC | D18: (Piloto) NFR em pipeline com baseline e evidência (evitar atuação reativa) - Cartões | E18: Pipeline NFR rodando + report versionado + baseline coletado (2–4 semanas) + registro de execução | G18: 1 | H18: =IF(G18=1,"PLANEJADO",IF(G18=1.5,"DESENVOLVENDO",IF(G18=2,"EM ADOÇÃO",IF(G18=3,"ADOTADO","")))) -> PLANEJADO
A20: SQUAD | B20: ID_MELHORIA | C20: NÍVEL E ÁREA DE PROCESSO | D20: ENTREGÁVEL | E20: DOR (DEFINITION OF DONE) | F20: EVIDÊNCIAS | G20: SCORE | H20: STATUS
A21: DEMONSTRAÇÕES | B21: T1-N2-N3-01 | C21: N2 – Ambiente de Testes N3 – Organização de Testes | D21: (MVP) Governança mínima de STG (regras, janelas, massa e auditoria) | E21: Regras publicadas + controle de acesso + janelas definidas + procedimento de restauração de massa + registro/auditoria (quem/quando/o quê) | G21: 1 | H21: =IF(G21=1,"PLANEJADO",IF(G21=1.5,"DESENVOLVENDO",IF(G21=2,"EM ADOÇÃO",IF(G21=3,"ADOTADO","")))) -> PLANEJADO
B22: T1-N2-04 | C22: N2 – Planejamento de Testes - Levantamento | D22: (MVP) Levantar testes prioritários por risco por squad (P1/P2/P3) e registrar no Azure | E22: Lista dos testes de regressão priorizados P1/P2/P3 no Azure + critério de priorização | G22: 1 | H22: =IF(G22=1,"PLANEJADO",IF(G22=1.5,"DESENVOLVENDO",IF(G22=2,"EM ADOÇÃO",IF(G22=3,"ADOTADO","")))) -> PLANEJADO
B23: T1-N2-05 | C23: N2 – Planejamento de Testes - Revisão | D23: (MVP) Revisar P1/P2/P3 existente (sanidade e atualização mínima) | E23: Revisão registrada (data) + ajustes se necessário + link no Azure | G23: 1 | H23: =IF(G23=1,"PLANEJADO",IF(G23=1.5,"DESENVOLVENDO",IF(G23=2,"EM ADOÇÃO",IF(G23=3,"ADOTADO","")))) -> PLANEJADO
B24: T1-N2-07 | C24: N2 – Desenho e Execução de Testes | D24: (MVP) Migrar 20% dos testes automatizados do Robot para Playwright (baseline Q1, priorização por risco) | E24: Baseline Robot (data de corte) + lista migrada + evidência de execução; foco preferencial em P1 | G24: 1 | H24: =IF(G24=1,"PLANEJADO",IF(G24=1.5,"DESENVOLVENDO",IF(G24=2,"EM ADOÇÃO",IF(G24=3,"ADOTADO","")))) -> PLANEJADO
B25: T1-N2-N3-06 | C25: N3 – Integração dos Testes ao SDLC N2 – Ambiente de Testes | D25: (MVP) Rodar automação em pipeline (template padrão replicável) para regressão P1 | E25: Pipeline rodando + gatilho definido + artefatos (report/log) + doc mínima | G25: 1 | H25: =IF(G25=1,"PLANEJADO",IF(G25=1.5,"DESENVOLVENDO",IF(G25=2,"EM ADOÇÃO",IF(G25=3,"ADOTADO","")))) -> PLANEJADO
B26: T1-N2-08 | C26: N2 – Desenho e Execução de Testes | D26: (MVP) Automatizar o mínimo viável de P1 no Playwright por squad (regressão crítica) | E26: Suites P1 + report/log + padrão de código aplicado + rastreio com PBI/Plano | G26: 1 | H26: =IF(G26=1,"PLANEJADO",IF(G26=1.5,"DESENVOLVENDO",IF(G26=2,"EM ADOÇÃO",IF(G26=3,"ADOTADO","")))) -> PLANEJADO
B27: T1-N2-09 | C27: N2 – Desenho e Execução N2 – Monitoramento e Controle | D27: (Aplicado via Playwright) Evidência padronizada de execução (report/log) | E27: Evidência já gerada nos reports do Playwright e anexada/armazenada conforme padrão do repo/pipeline | G27: 1 | H27: =IF(G27=1,"PLANEJADO",IF(G27=1.5,"DESENVOLVENDO",IF(G27=2,"EM ADOÇÃO",IF(G27=3,"ADOTADO","")))) -> PLANEJADO
B28: T1-N3-10 | C28: N3 – Revisões Técnicas | D28: (MVP) Qualidade do PBI: manter média ≥3 no Q1 (campo oficial) | E28: Rubrica/checklist por PBI + relatório mensal com média ≥3 | G28: 1 | H28: =IF(G28=1,"PLANEJADO",IF(G28=1.5,"DESENVOLVENDO",IF(G28=2,"EM ADOÇÃO",IF(G28=3,"ADOTADO","")))) -> PLANEJADO
B29: T1-N2-N3-11 | C29: N2 – Desenho e Execução N3 – Integração SDLC | D29: (Stretch – faseado internamente) Avançar cobertura de regressão automatizada dos endpoints críticos (baseline Q1) | E29: Baseline endpoints críticos datado + mapeamento endpoint→teste + evolução mensal comprovada por execução em pipeline | G29: 1 | H29: =IF(G29=1,"PLANEJADO",IF(G29=1.5,"DESENVOLVENDO",IF(G29=2,"EM ADOÇÃO",IF(G29=3,"ADOTADO","")))) -> PLANEJADO
B30: T1-N3-12 | C30: N3 – Testes Não Funcionais | D30: (MVP) Estratégia NFR “Lite” por produto/jornada (o que medir, quando rodar, critérios e evidência) | E30: Documento Lite publicado + backlog NFR priorizado por risco + cadência definida | G30: 1 | H30: =IF(G30=1,"PLANEJADO",IF(G30=1.5,"DESENVOLVENDO",IF(G30=2,"EM ADOÇÃO",IF(G30=3,"ADOTADO","")))) -> PLANEJADO
B31: T1-N3-13 | C31: N3 – Testes Não Funcionais (piloto) N3 – Integração ao SDLC | D31: (Piloto) NFR em pipeline com baseline e evidência (evitar atuação reativa) - Cartões | E31: Pipeline NFR rodando + report versionado + baseline coletado (2–4 semanas) + registro de execução | G31: 1 | H31: =IF(G31=1,"PLANEJADO",IF(G31=1.5,"DESENVOLVENDO",IF(G31=2,"EM ADOÇÃO",IF(G31=3,"ADOTADO","")))) -> PLANEJADO
A33: SQUAD | B33: ID_MELHORIA | C33: NÍVEL E ÁREA DE PROCESSO | D33: ENTREGÁVEL | E33: DOR (DEFINITION OF DONE) | F33: EVIDÊNCIAS | G33: SCORE | H33: STATUS
A34: OPERAÇÕES | B34: T1-N2-N3-01 | C34: N2 – Ambiente de Testes N3 – Organização de Testes | D34: (MVP) Governança mínima de STG (regras, janelas, massa e auditoria) | E34: Regras publicadas + controle de acesso + janelas definidas + procedimento de restauração de massa + registro/auditoria (quem/quando/o quê) | G34: 1 | H34: =IF(G34=1,"PLANEJADO",IF(G34=1.5,"DESENVOLVENDO",IF(G34=2,"EM ADOÇÃO",IF(G34=3,"ADOTADO","")))) -> PLANEJADO
B35: T1-N2-04 | C35: N2 – Planejamento de Testes - Levantamento | D35: (MVP) Levantar testes prioritários por risco por squad (P1/P2/P3) e registrar no Azure | E35: Lista dos testes de regressão priorizados P1/P2/P3 no Azure + critério de priorização | G35: 1 | H35: =IF(G35=1,"PLANEJADO",IF(G35=1.5,"DESENVOLVENDO",IF(G35=2,"EM ADOÇÃO",IF(G35=3,"ADOTADO","")))) -> PLANEJADO
B36: T1-N2-05 | C36: N2 – Planejamento de Testes - Revisão | D36: (MVP) Revisar P1/P2/P3 existente (sanidade e atualização mínima) | E36: Revisão registrada (data) + ajustes se necessário + link no Azure | G36: 1 | H36: =IF(G36=1,"PLANEJADO",IF(G36=1.5,"DESENVOLVENDO",IF(G36=2,"EM ADOÇÃO",IF(G36=3,"ADOTADO","")))) -> PLANEJADO
B37: T1-N2-07 | C37: N2 – Desenho e Execução de Testes | D37: (MVP) Migrar 20% dos testes automatizados do Robot para Playwright (baseline Q1, priorização por risco) | E37: Baseline Robot (data de corte) + lista migrada + evidência de execução; foco preferencial em P1 | G37: 1 | H37: =IF(G37=1,"PLANEJADO",IF(G37=1.5,"DESENVOLVENDO",IF(G37=2,"EM ADOÇÃO",IF(G37=3,"ADOTADO","")))) -> PLANEJADO
B38: T1-N2-N3-06 | C38: N3 – Integração dos Testes ao SDLC N2 – Ambiente de Testes | D38: (MVP) Rodar automação em pipeline (template padrão replicável) para regressão P1 | E38: Pipeline rodando + gatilho definido + artefatos (report/log) + doc mínima | G38: 1 | H38: =IF(G38=1,"PLANEJADO",IF(G38=1.5,"DESENVOLVENDO",IF(G38=2,"EM ADOÇÃO",IF(G38=3,"ADOTADO","")))) -> PLANEJADO
B39: T1-N2-08 | C39: N2 – Desenho e Execução de Testes | D39: (MVP) Automatizar o mínimo viável de P1 no Playwright por squad (regressão crítica) | E39: Suites P1 + report/log + padrão de código aplicado + rastreio com PBI/Plano | G39: 1 | H39: =IF(G39=1,"PLANEJADO",IF(G39=1.5,"DESENVOLVENDO",IF(G39=2,"EM ADOÇÃO",IF(G39=3,"ADOTADO","")))) -> PLANEJADO
B40: T1-N2-09 | C40: N2 – Desenho e Execução N2 – Monitoramento e Controle | D40: (Aplicado via Playwright) Evidência padronizada de execução (report/log) | E40: Evidência já gerada nos reports do Playwright e anexada/armazenada conforme padrão do repo/pipeline | G40: 1 | H40: =IF(G40=1,"PLANEJADO",IF(G40=1.5,"DESENVOLVENDO",IF(G40=2,"EM ADOÇÃO",IF(G40=3,"ADOTADO","")))) -> PLANEJADO
B41: T1-N3-10 | C41: N3 – Revisões Técnicas | D41: (MVP) Qualidade do PBI: manter média ≥3 no Q1 (campo oficial) | E41: Rubrica/checklist por PBI + relatório mensal com média ≥3 | G41: 1 | H41: =IF(G41=1,"PLANEJADO",IF(G41=1.5,"DESENVOLVENDO",IF(G41=2,"EM ADOÇÃO",IF(G41=3,"ADOTADO","")))) -> PLANEJADO
B42: T1-N2-N3-11 | C42: N2 – Desenho e Execução N3 – Integração SDLC | D42: (Stretch – faseado internamente) Avançar cobertura de regressão automatizada dos endpoints críticos (baseline Q1) | E42: Baseline endpoints críticos datado + mapeamento endpoint→teste + evolução mensal comprovada por execução em pipeline | G42: 1 | H42: =IF(G42=1,"PLANEJADO",IF(G42=1.5,"DESENVOLVENDO",IF(G42=2,"EM ADOÇÃO",IF(G42=3,"ADOTADO","")))) -> PLANEJADO
B43: T1-N3-12 | C43: N3 – Testes Não Funcionais | D43: (MVP) Estratégia NFR “Lite” por produto/jornada (o que medir, quando rodar, critérios e evidência) | E43: Documento Lite publicado + backlog NFR priorizado por risco + cadência definida | G43: 1 | H43: =IF(G43=1,"PLANEJADO",IF(G43=1.5,"DESENVOLVENDO",IF(G43=2,"EM ADOÇÃO",IF(G43=3,"ADOTADO","")))) -> PLANEJADO
...

Sheet ANUAL - Roadmap por Squads
A1: ID Melhoria | B1: Trimestre | C1: Fase | D1: Squad | E1: Entrega | F1: TMMi (Nível – Área) | G1: Envolvidos | H1: Evidência / DOR (Definition of Ready) | I1: Status Geral | J1: Responsável
A2: T1-N2-N3-01 | B2: TRI 1 | C2: Engenharia e Governança | D2: Todas (TAG) | E2: (MVP) Governança mínima de STG (regras, janelas, massa e auditoria) | F2: N2 – Ambiente de Testes / N3 – Organização de Testes | G2: Cloud / Engenharia / QA / Tech Leads | H2: Regras publicadas + controle de acesso + janelas definidas + procedimento de restauração de massa + registro/auditoria (quem/quando/o quê) | I2: Planejado | J2: Cloud + QA Chapter
A3: T1-N2-02 | B3: TRI 1 | C3: QA (Governança) | D3: Todas (TAG) | E3: (MVP) Política de Testes “Lite” (1 página) | F3: N2 – Política de Testes | G3: QA / Gestão | H3: Documento publicado (escopo, papéis, critérios mínimos, evidência mínima, compliance) + comunicação oficial | I3: Planejado | J3: QA Chapter
A4: T1-N2-N4-03 | B4: TRI 1 | C4: Melhoria Contínua | D4: Todas (TAG) | E4: (MVP) Indicadores comparáveis (baseline + tendência) + 3 gatilhos de ação | F4: N4 – Medição dos Testes (início) / N2 – Monitoramento e Controle | G4: QA / Gestão | H4: Dashboard publicado + definições + tendência trimestral + gatilhos e ações padrão documentados | I4: Planejado | J4: QA Chapter
A5: T1-N2-04 | B5: TRI 1 | C5: Engenharia de Qualidade | D5: Todas exceto: Plataforma (Cartões) e Consent+Interop (Duplicatas) | E5: (MVP) Levantar testes prioritários por risco por squad (P1/P2/P3) e registrar no Azure | F5: N2 – Planejamento de Testes | G5: QA / Produto / Squad | H5: Lista dos testes de regressão priorizados P1/P2/P3 no Azure + critério de priorização | I5: Planejado | J5: QAs por squad + Produto
A6: T1-N2-05 | B6: TRI 1 | C6: Engenharia de Qualidade | D6: Plataforma (Cartões) + Consent e Interop (Duplicatas) | E6: (MVP) Revisar P1/P2/P3 existente (sanidade e atualização mínima) | F6: N2 – Planejamento de Testes | G6: QA / Produto / Squad | H6: Revisão registrada (data) + ajustes se necessário + link no Azure | I6: Planejado | J6: QAs dessas squads + Produto
A7: T1-N2-N3-06 | B7: TRI 1 | C7: QA + Cloud | D7: Cartões + Duplicatas | E7: (MVP) Rodar automação em pipeline (template padrão replicável) para regressão P1 | F7: N3 – Integração dos Testes ao SDLC / N2 – Ambiente de Testes | G7: QA / Cloud / DevOps | H7: Pipeline rodando + gatilho definido + artefatos (report/log) + doc mínima | I7: Planejado | J7: Trombeta + Cloud
A8: T1-N2-07 | B8: TRI 1 | C8: Engenharia de Qualidade | D8: Cartões (todas as squads) exceto Plataforma | E8: (MVP) Migrar 20% dos testes automatizados do Robot para Playwright (baseline Q1, priorização por risco) | F8: N2 – Desenho e Execução de Testes | G8: QA / QEs / Dev (apoio) | H8: Baseline Robot (data de corte) + lista migrada + evidência de execução; foco preferencial em P1 | I8: Planejado | J8: QAs Cartões Anselmo
A9: T1-N2-08 | B9: TRI 1 | C9: Engenharia de Qualidade | D9: Cartões + Duplicatas (onde aplicável) | E9: (MVP) Automatizar o mínimo viável de P1 no Playwright por squad (regressão crítica) | F9: N2 – Desenho e Execução de Testes | G9: QA / QEs / Dev (apoio) | H9: Suites P1 + report/log + padrão de código aplicado + rastreio com PBI/Plano | I9: Planejado | J9: QAs por squad
A10: T1-N2-09 | B10: TRI 1 | C10: Engenharia de Qualidade | D10: Todas (TAG) | E10: (Aplicado via Playwright) Evidência padronizada de execução (report/log) | F10: N2 – Desenho e Execução / N2 – Monitoramento e Controle | G10: QA | H10: Evidência já gerada nos reports do Playwright e anexada/armazenada conforme padrão do repo/pipeline | I10: Adotado | J10: QAs (via padrão Playwright)
A11: T1-N3-10 | B11: TRI 1 | C11: Engenharia de Qualidade | D11: Duplicatas (Interop + Negotiation) | E11: (MVP) Qualidade do PBI: manter média ≥3 no Q1 (campo oficial) | F11: N3 – Revisões Técnicas (Quality Review) | G11: QA / Produto / Squad | H11: Rubrica/checklist por PBI + relatório mensal com média ≥3 | I11: Planejado | J11: André + Trombeta
A12: T1-N2-N3-11 | B12: TRI 1 | C12: Engenharia de Qualidade | D12: Duplicatas (Interop + Negotiation) | E12: (Stretch – faseado internamente) Avançar cobertura de regressão automatizada dos endpoints críticos (baseline Q1) | F12: N2 – Desenho e Execução / N3 – Integração SDLC | G12: QA / QEs / Dev (apoio) | H12: Baseline endpoints críticos datado + mapeamento endpoint→teste + evolução mensal comprovada por execução em pipeline | I12: Planejado | J12: André + Trombeta
... A25: T4-N4-03 | B25: TRI 4 | C25: Gestão | D25: Produtos: Cartões + Duplicatas | E25: Relatório executivo anual orientado por dados (incluindo NFR) | F25: N4 – Medição dos Testes | G25: QA / Gestão | H25: Relatório anual com tendências, decisões tomadas e próximos focos | I25: Planejado | J25: QA Chapter

Sheet Mapa do TMMi
B2: Mapa do TMMi (O que tem em casa nível)
B3: Nível | C3: Área de Processo | D3: Descrição
B4: 2 | C4: Política e Estratégia de Testes | D4: TMMi Nível 2 — Gerenciado Aqui a organização estabelece o jeito básico de testar e consegue gerenciar isso no projeto. Pode variar de um projeto para outro, mas já existe direção clara (principalmente via política e estratégia de testes) e já acontece: 1- Planejamento 2 - Monitoramento e controle 3 - Técnicas de desenho de testes 4 - Controle da execução 5 - Ambientes de teste disponíveis para os testes (STG) Em uma frase: testar deixa de ser improviso e vira rotina controlada por projeto.
B5: 2 | C5: Planejamento de Testes
B6: 2 | C6: Monitoramento e Controle dos Testes
B7: 2 | C7: Desenho e Execução de Testes
B8: 2 | C8: Gerenciamento de Defeitos
B9: 2 | C9: Ambiente de Testes
B10: 3 | C10: Organização de Testes | D10: TMMi Nível 3 — Definido Aqui para de ser “cada projeto do seu jeito” e vira padrão da organização: todos os projetos seguem os mesmos padrões e procedimentos. Além do N2 continuar existindo, agora nós temos: 1 - Times organizados para teste 2 - Programa de treinamento 3 - Teste integrado ao ciclo de desenvolvimento e entrando cedo 4 - Testes não funcionais planejados e executados em todos os projetos 5 - Revisões (reviews) acontecendo em cada projeto Em uma frase: qualidade vira processo organizacional, não esforço heroico.
B11: 3 | C11: Programa de Treinamento em Testes
B12: 3 | C12: Integração dos Testes ao SDLC
B13: 3 | C13: Testes Não Funcionais
B14: 3 | C14: Revisões Técnicas (Quality Review)
B15: 4 | C15: Medição dos Testes | D15: TMMi Nível 4 — Medido Aqui o diferencial é medição forte e cedo: medir atividades e resultados de forma consistente, desde o início, para garantir que em cada etapa o produto esteja o mais “livre de defeitos possível”. E entram revisões avançadas em todos os projetos, evoluindo o que começou no nível 3. Em uma frase: qualidade passa a ser guiada por dados e previsibilidade, não só percepção.
B16: 4 | C16: Avaliação da Qualidade do Produto
B17: 4 | C17: Revisões Avançadas
B18: 5 | C18: Prevenção de Defeitos | D18: TMMi Nível 5 — Otimização Aqui tudo é avaliado (atividades e resultados) e existem ações de otimização para manter melhoria contínua, com foco em: 1 - Prevenção de defeitos 2 - Qualidade otimizada Em uma frase: a organização aprende, ajusta e previne — continuamente.
B19: 5 | C19: Controle da Qualidade
B20: 5 | C20: Otimização do Processo de Testes
B22: Fonte: https://www.tmmi.org/

Sheet Entregue x Esperado TMMi
B2: Entregue x Esperado pelo TMMi
B4: Fase | C4: Nível e Área de Processo | D4: Entregue na TAG (observação) | E4: Esperado pelo TMMi (gap)
B5: N2 – Gerenciado | C5: N2 – Política de Testes | D5: Diretrizes na prática (escopo downstream, padrões mínimos, criticidade C0–C2), porém política institucional formal ainda não fechada. | E5: Formalizar e publicar a política (objetivo, escopo, responsabilidades, compliance) para institucionalizar.
B6: N2 – Gerenciado | C6: N2 – Estratégia de Testes | D6: Estratégia prática implementada (modelo de atuação do QA, padrões de evidência/defeito/métricas, foco em risco/criticidade). | E6: Consolidar a estratégia como referência única (níveis de teste, critérios de aplicação e adaptação por produto/squad).
B7: N2 – Gerenciado | C7: N2 – Planejamento de Testes | D7: Artefatos de planejamento (manual/planilha), priorização por criticidade, organização no Azure Test Plans. | E7: Explicitar critérios de entrada/saída e gestão de risco por jornada (reduzir variação por squad).
B8: N2 – Gerenciado | C8: N2 – Monitoramento e Controle dos Testes | D8: Dashboards/métricas operacionais no Azure, acompanhamento por execução/defeitos. | E8: Definir gatilhos de ação (limiares e resposta padrão: replanejar, travar release, ampliar escopo etc.).
B9: N2 – Gerenciado | C9: N2 – Desenho e Execução de Testes | D9: Padrões de evidência, execução estruturada e organização de testes (incluindo estrutura por Swagger/rotas no Azure). | E9: Ampliar reuso e cobertura prioritária por jornada (menos por sprint, mais por risco do produto).
B10: N2 – Gerenciado | C10: N2 – Gerenciamento de Defeitos | D10: Fluxo de bugs com evidência obrigatória, criticidade C0/C1/C2, rastreabilidade com PBIs. | E10: Transformar tendência de defeitos em ações recorrentes (ponte para N4/N5: prevenção e otimização).
B11: N2 – Gerenciado | C11: N2 – Ambiente de Testes | D11: Boas práticas/documentação de ambientes e execução de automação em nuvem via pipeline (Playwright) para 2 squads. | E11: Estabelecer governança do ambiente (uso, dados, estabilidade) e evoluir ambiente isolado como capability institucional.
B12: N3 – Definido | C12: N3 – Organização de Testes | D12: Chapter de QA e alinhamento de papéis/responsabilidades com PMs (tríade) e squads. | E12: Formalizar o modelo organizacional (papéis, cadência, governança e critérios de maturidade por squad).
B13: N3 – Definido | C13: N3 – Programa de Treinamento em Testes | D13: Mini-treinamentos recorrentes e materiais de boas práticas (ex.: automação). | E13: Criar trilha mínima e registro (onboarding + evolução por papel, não só conteúdo pontual).
B14: N3 – Definido | C14: N3 – Integração dos Testes ao SDLC | D14: Quality Review no refinamento e integração QA–Produto–Dev em squads mais maduras. | E14: Tornar padrão para todas as squads (entrada cedo e consistente, reduzindo dependência do QA como gatilho). SHIFTLEFT Testing
B15: N3 – Definido | C15: N3 – Testes Não Funcionais | D15: Validações pontuais (ex.: performance/segurança) e suporte quando demandado. | E15: Definir estratégia de NFR por produto/jornada (o que medir, quando rodar, critérios e evidência), evitando atuação só reativa.
... B22: N5 – Otimização | C22: N5 - Otimização do Processo de Testes | D22: Melhoria contínua em curso (trabalho de base + engenharia), porém ainda por iniciativa e ciclo. | E22: Implementar otimização contínua institucional com metas, medição e ajustes sistemáticos (ciclo fechado N4→N5).

Sheet Critérios TMMi
A1: ID MELHORIA | B1: TRIMESTRE | C1: SQUAD | D1: ENTREGA | E1: SUBCRITÉRIO | F1: PESO | G1: ATENDIDO | H1: LINK DA EVIDÊNCIA | I1: OBS | J1: DATA
A2: T1-N2-N3-01 | D2: Governança mínima de STG (regras, janelas, massa e auditoria) | E2: Regras publicadas
A3: T1-N2-N3-01 | D3: Governança mínima de STG (regras, janelas, massa e auditoria) | E3: Controle de acesso definido/aplicado
A4: T1-N2-N3-01 | D4: Governança mínima de STG (regras, janelas, massa e auditoria) | E4: Janelas de uso definidas e comunicadas
A5: T1-N2-N3-01 | D5: Governança mínima de STG (regras, janelas, massa e auditoria) | E5: Procedimento de restauração de massa definido
A6: T1-N2-N3-01 | D6: Governança mínima de STG (regras, janelas, massa e auditoria) | E6: Registro/auditoria de execuções (quem/quando/o quê)
A8: T1-N2-02 | D8: Política de Testes “Lite” (1 página) | E8: Documento publicado
A9: T1-N2-02 | D9: Política de Testes “Lite” (1 página) | E9: Escopo/papéis definidos
A10: T1-N2-02 | D10: Política de Testes “Lite” (1 página) | E10: Critérios mínimos + evidência mínima definidos
A11: T1-N2-02 | D11: Política de Testes “Lite” (1 página) | E11: Comunicação oficial realizada
A13: T1-N2-N4-03 | D13: Indicadores comparáveis (baseline+tendência) + gatilhos de ação | E13: Dashboard publicado
A14: T1-N2-N4-03 | D14: Indicadores comparáveis (baseline+tendência) + gatilhos de ação | E14: Definições dos indicadores (glossário)
A15: T1-N2-N4-03 | D15: Indicadores comparáveis (baseline+tendência) + gatilhos de ação | E15: Baseline datado (ponto zero)
... A115: T1-N3-14 | D115: NFR em pipeline (piloto) | E115: Registro de execuções
